Workbook

Sheet Resumen
A1: Reporte de cumplimiento — Estándar general de seguridad, autenticación y autorización
A2: Hojas: Resultados (detalle, evidencia y seguimiento; lo abierto y más grave va primero) · Pruebas y checklist · Referencia (leyenda y reglas del estándar).
A3: Proyecto | B3: FideiNexus - Modulo de Solicitudes
A4: Versión del estándar | B4: 1.0.0 (Propuesta para revisión)
A5: Fecha del análisis | B5: 2026-10-21
A6: Generado por | B6: Agente de verificación del estándar
A7: Alcance revisado | B7: 4 microservicios (requests, preparation, celebration, certificate) + frontend Angular + gateway, auditados contra SEC-001..SEC-022
A9: Veredicto automático | B9: =IF(COUNTIFS(Resultados!$F$2:$F$2000,"DEBE",Resultados!$H$2:$H$2000,"NO_CUMPLE")>0,"NO APTO PARA APROBAR: hay incumplimientos de requisitos obligatorios (DEBE)",IF(COUNTIF(Resultados!$H$2:$H$2000,"SIN_EVALUAR")+COUNTIF(Resultados!$H$2:$H$2000,"REQUIERE_REVISION_MANUAL")+COUNTIFS(Resultados!$F$2:$F$2000,"DEBE",Resultados!$H$2:$H$2000,"PARCIAL")>0,"APROBACIÓN CONDICIONADA: hay verificaciones pendientes o cumplimientos parciales en requisitos DEBE","APTO (según evidencia revisada): sin incumplimientos obligatorios ni pendientes"))
A11: Indicadores clave
A12: Evaluaciones realizadas (componente × regla) | B12: =COUNTA(Resultados!$A$2:$A$2000)
A13: Cobertura de la evaluación (reglas aplicables que se pudieron decidir) | B13: =IFERROR((COUNTIF(Resultados!$H$2:$H$2000,"CUMPLE")+COUNTIF(Resultados!$H$2:$H$2000,"PARCIAL")+COUNTIF(Resultados!$H$2:$H$2000,"NO_CUMPLE"))/(COUNTA(Resultados!$A$2:$A$2000)-COUNTIF(Resultados!$H$2:$H$2000,"NO_APLICA")),"")
A14: Cumplimiento global (ponderado) | B14: =IFERROR(SUM(Resultados!$J$2:$J$2000)/COUNT(Resultados!$J$2:$J$2000),"")
A15: Cumplimiento en requisitos obligatorios (DEBE) | B15: =IFERROR(SUMIFS(Resultados!$J$2:$J$2000,Resultados!$F$2:$F$2000,"DEBE")/COUNTIFS(Resultados!$F$2:$F$2000,"DEBE",Resultados!$J$2:$J$2000,">=0"),"")
A16: Cumplimiento en recomendaciones (DEBERÍA) | B16: =IFERROR(SUMIFS(Resultados!$J$2:$J$2000,Resultados!$F$2:$F$2000,"DEBERÍA")/COUNTIFS(Resultados!$F$2:$F$2000,"DEBERÍA",Resultados!$J$2:$J$2000,">=0"),"")
A17: Incumplimientos obligatorios abiertos (DEBE en NO_CUMPLE) | B17: =COUNTIFS(Resultados!$F$2:$F$2000,"DEBE",Resultados!$H$2:$H$2000,"NO_CUMPLE")
A18: Reglas distintas incumplidas (NO_CUMPLE) | B18: =SUMPRODUCT((Resultados!$H$2:$H$2000="NO_CUMPLE")/(COUNTIFS(Resultados!$C$2:$C$2000,Resultados!$C$2:$C$2000,Resultados!$H$2:$H$2000,"NO_CUMPLE")+(Resultados!$H$2:$H$2000<>"NO_CUMPLE")))
A19: El % pondera CUMPLE=1, PARCIAL=0.5 (ajustable en Referencia) y NO_CUMPLE=0; NO_APLICA, REQUIERE_REVISION_MANUAL y SIN_EVALUAR no puntúan, así que léalo junto a la cobertura.
A21: Distribución por estado
A22: Estado | B22: Cantidad | C22: % del total
A23: CUMPLE | B23: =COUNTIF(Resultados!$H$2:$H$2000,A23) | C23: =IFERROR(B23/B$29,0)
A24: PARCIAL | B24: =COUNTIF(Resultados!$H$2:$H$2000,A24) | C24: =IFERROR(B24/B$29,0)
A25: NO_CUMPLE | B25: =COUNTIF(Resultados!$H$2:$H$2000,A25) | C25: =IFERROR(B25/B$29,0)
A26: NO_APLICA | B26: =COUNTIF(Resultados!$H$2:$H$2000,A26) | C26: =IFERROR(B26/B$29,0)
A27: REQUIERE_REVISION_MANUAL | B27: =COUNTIF(Resultados!$H$2:$H$2000,A27) | C27: =IFERROR(B27/B$29,0)
A28: SIN_EVALUAR | B28: =COUNTIF(Resultados!$H$2:$H$2000,A28) | C28: =IFERROR(B28/B$29,0)
A29: Total | B29: =SUM(B23:B28) | C29: =SUM(C23:C28)
A31: Cumplimiento por componente
A32: Componente | B32: Tipo | C32: CUMPLE | D32: PARCIAL | E32: NO_CUMPLE | F32: NO_APLICA | G32: REQUIERE_REVISION_MANUAL | H32: SIN_EVALUAR | I32: % cumplimiento
A33: svc-requests | B33: microservicio | C33: =COUNTIFS(Resultados!$A$2:$A$2000,$A33,Resultados!$H$2:$H$2000,C$32) | D33: =COUNTIFS(Resultados!$A$2:$A$2000,$A33,Resultados!$H$2:$H$2000,D$32) | E33: =COUNTIFS(Resultados!$A$2:$A$2000,$A33,Resultados!$H$2:$H$2000,E$32) | F33: =COUNTIFS(Resultados!$A$2:$A$2000,$A33,Resultados!$H$2:$H$2000,F$32) | G33: =COUNTIFS(Resultados!$A$2:$A$2000,$A33,Resultados!$H$2:$H$2000,G$32) | H33: =COUNTIFS(Resultados!$A$2:$A$2000,$A33,Resultados!$H$2:$H$2000,H$32) | I33: =IFERROR(SUMIFS(Resultados!$J$2:$J$2000,Resultados!$A$2:$A$2000,$A33)/COUNTIFS(Resultados!$A$2:$A$2000,$A33,Resultados!$J$2:$J$2000,">=0"),"")
A34: svc-preparation | B34: microservicio | C34: =COUNTIFS(Resultados!$A$2:$A$2000,$A34,Resultados!$H$2:$H$2000,C$32) | D34: =COUNTIFS(Resultados!$A$2:$A$2000,$A34,Resultados!$H$2:$H$2000,D$32) | E34: =COUNTIFS(Resultados!$A$2:$A$2000,$A34,Resultados!$H$2:$H$2000,E$32) | F34: =COUNTIFS(Resultados!$A$2:$A$2000,$A34,Resultados!$H$2:$H$2000,F$32) | G34: =COUNTIFS(Resultados!$A$2:$A$2000,$A34,Resultados!$H$2:$H$2000,G$32) | H34: =COUNTIFS(Resultados!$A$2:$A$2000,$A34,Resultados!$H$2:$H$2000,H$32) | I34: =IFERROR(SUMIFS(Resultados!$J$2:$J$2000,Resultados!$A$2:$A$2000,$A34)/COUNTIFS(Resultados!$A$2:$A$2000,$A34,Resultados!$J$2:$J$2000,">=0"),"")
A35: svc-celebration | B35: microservicio | C35: =COUNTIFS(Resultados!$A$2:$A$2000,$A35,Resultados!$H$2:$H$2000,C$32) | D35: =COUNTIFS(Resultados!$A$2:$A$2000,$A35,Resultados!$H$2:$H$2000,D$32) | E35: =COUNTIFS(Resultados!$A$2:$A$2000,$A35,Resultados!$H$2:$H$2000,E$32) | F35: =COUNTIFS(Resultados!$A$2:$A$2000,$A35,Resultados!$H$2:$H$2000,F$32) | G35: =COUNTIFS(Resultados!$A$2:$A$2000,$A35,Resultados!$H$2:$H$2000,G$32) | H35: =COUNTIFS(Resultados!$A$2:$A$2000,$A35,Resultados!$H$2:$H$2000,H$32) | I35: =IFERROR(SUMIFS(Resultados!$J$2:$J$2000,Resultados!$A$2:$A$2000,$A35)/COUNTIFS(Resultados!$A$2:$A$2000,$A35,Resultados!$J$2:$J$2000,">=0"),"")
A36: svc-certificate | B36: microservicio | C36: =COUNTIFS(Resultados!$A$2:$A$2000,$A36,Resultados!$H$2:$H$2000,C$32) | D36: =COUNTIFS(Resultados!$A$2:$A$2000,$A36,Resultados!$H$2:$H$2000,D$32) | E36: =COUNTIFS(Resultados!$A$2:$A$2000,$A36,Resultados!$H$2:$H$2000,E$32) | F36: =COUNTIFS(Resultados!$A$2:$A$2000,$A36,Resultados!$H$2:$H$2000,F$32) | G36: =COUNTIFS(Resultados!$A$2:$A$2000,$A36,Resultados!$H$2:$H$2000,G$32) | H36: =COUNTIFS(Resultados!$A$2:$A$2000,$A36,Resultados!$H$2:$H$2000,H$32) | I36: =IFERROR(SUMIFS(Resultados!$J$2:$J$2000,Resultados!$A$2:$A$2000,$A36)/COUNTIFS(Resultados!$A$2:$A$2000,$A36,Resultados!$J$2:$J$2000,">=0"),"")
A37: web-fideinexus | B37: frontend | C37: =COUNTIFS(Resultados!$A$2:$A$2000,$A37,Resultados!$H$2:$H$2000,C$32) | D37: =COUNTIFS(Resultados!$A$2:$A$2000,$A37,Resultados!$H$2:$H$2000,D$32) | E37: =COUNTIFS(Resultados!$A$2:$A$2000,$A37,Resultados!$H$2:$H$2000,E$32) | F37: =COUNTIFS(Resultados!$A$2:$A$2000,$A37,Resultados!$H$2:$H$2000,F$32) | G37: =COUNTIFS(Resultados!$A$2:$A$2000,$A37,Resultados!$H$2:$H$2000,G$32) | H37: =COUNTIFS(Resultados!$A$2:$A$2000,$A37,Resultados!$H$2:$H$2000,H$32) | I37: =IFERROR(SUMIFS(Resultados!$J$2:$J$2000,Resultados!$A$2:$A$2000,$A37)/COUNTIFS(Resultados!$A$2:$A$2000,$A37,Resultados!$J$2:$J$2000,">=0"),"")
A38: gateway | B38: gateway | C38: =COUNTIFS(Resultados!$A$2:$A$2000,$A38,Resultados!$H$2:$H$2000,C$32) | D38: =COUNTIFS(Resultados!$A$2:$A$2000,$A38,Resultados!$H$2:$H$2000,D$32) | E38: =COUNTIFS(Resultados!$A$2:$A$2000,$A38,Resultados!$H$2:$H$2000,E$32) | F38: =COUNTIFS(Resultados!$A$2:$A$2000,$A38,Resultados!$H$2:$H$2000,F$32) | G38: =COUNTIFS(Resultados!$A$2:$A$2000,$A38,Resultados!$H$2:$H$2000,G$32) | H38: =COUNTIFS(Resultados!$A$2:$A$2000,$A38,Resultados!$H$2:$H$2000,H$32) | I38: =IFERROR(SUMIFS(Resultados!$J$2:$J$2000,Resultados!$A$2:$A$2000,$A38)/COUNTIFS(Resultados!$A$2:$A$2000,$A38,Resultados!$J$2:$J$2000,">=0"),"")
A57: Cumplimiento por categoría del estándar
A58: Categoría | B58: Evaluaciones | C58: CUMPLE | D58: PARCIAL | E58: NO_CUMPLE | F58: NO_APLICA | G58: REQUIERE_REVISION_MANUAL | H58: SIN_EVALUAR | I58: % cumplimiento
A59: Identidad y autenticación | B59: =COUNTIFS(Resultados!$E$2:$E$2000,$A59) | C59: =COUNTIFS(Resultados!$E$2:$E$2000,$A59,Resultados!$H$2:$H$2000,C$58) | D59: =COUNTIFS(Resultados!$E$2:$E$2000,$A59,Resultados!$H$2:$H$2000,D$58) | E59: =COUNTIFS(Resultados!$E$2:$E$2000,$A59,Resultados!$H$2:$H$2000,E$58) | F59: =COUNTIFS(Resultados!$E$2:$E$2000,$A59,Resultados!$H$2:$H$2000,F$58) | G59: =COUNTIFS(Resultados!$E$2:$E$2000,$A59,Resultados!$H$2:$H$2000,G$58) | H59: =COUNTIFS(Resultados!$E$2:$E$2000,$A59,Resultados!$H$2:$H$2000,H$58) | I59: =IFERROR(SUMIFS(Resultados!$J$2:$J$2000,Resultados!$E$2:$E$2000,$A59)/COUNTIFS(Resultados!$E$2:$E$2000,$A59,Resultados!$J$2:$J$2000,">=0"),"")
A60: Autorización y roles | B60: =COUNTIFS(Resultados!$E$2:$E$2000,$A60) | C60: =COUNTIFS(Resultados!$E$2:$E$2000,$A60,Resultados!$H$2:$H$2000,C$58) | D60: =COUNTIFS(Resultados!$E$2:$E$2000,$A60,Resultados!$H$2:$H$2000,D$58) | E60: =COUNTIFS(Resultados!$E$2:$E$2000,$A60,Resultados!$H$2:$H$2000,E$58) | F60: =COUNTIFS(Resultados!$E$2:$E$2000,$A60,Resultados!$H$2:$H$2000,F$58) | G60: =COUNTIFS(Resultados!$E$2:$E$2000,$A60,Resultados!$H$2:$H$2000,G$58) | H60: =COUNTIFS(Resultados!$E$2:$E$2000,$A60,Resultados!$H$2:$H$2000,H$58) | I60: =IFERROR(SUMIFS(Resultados!$J$2:$J$2000,Resultados!$E$2:$E$2000,$A60)/COUNTIFS(Resultados!$E$2:$E$2000,$A60,Resultados!$J$2:$J$2000,">=0"),"")
A61: Aislamiento multi-tenant | B61: =COUNTIFS(Resultados!$E$2:$E$2000,$A61) | C61: =COUNTIFS(Resultados!$E$2:$E$2000,$A61,Resultados!$H$2:$H$2000,C$58) | D61: =COUNTIFS(Resultados!$E$2:$E$2000,$A61,Resultados!$H$2:$H$2000,D$58) | E61: =COUNTIFS(Resultados!$E$2:$E$2000,$A61,Resultados!$H$2:$H$2000,E$58) | F61: =COUNTIFS(Resultados!$E$2:$E$2000,$A61,Resultados!$H$2:$H$2000,F$58) | G61: =COUNTIFS(Resultados!$E$2:$E$2000,$A61,Resultados!$H$2:$H$2000,G$58) | H61: =COUNTIFS(Resultados!$E$2:$E$2000,$A61,Resultados!$H$2:$H$2000,H$58) | I61: =IFERROR(SUMIFS(Resultados!$J$2:$J$2000,Resultados!$E$2:$E$2000,$A61)/COUNTIFS(Resultados!$E$2:$E$2000,$A61,Resultados!$J$2:$J$2000,">=0"),"")
A62: Seguridad entre microservicios | B62: =COUNTIFS(Resultados!$E$2:$E$2000,$A62) | C62: =COUNTIFS(Resultados!$E$2:$E$2000,$A62,Resultados!$H$2:$H$2000,C$58) | D62: =COUNTIFS(Resultados!$E$2:$E$2000,$A62,Resultados!$H$2:$H$2000,D$58) | E62: =COUNTIFS(Resultados!$E$2:$E$2000,$A62,Resultados!$H$2:$H$2000,E$58) | F62: =COUNTIFS(Resultados!$E$2:$E$2000,$A62,Resultados!$H$2:$H$2000,F$58) | G62: =COUNTIFS(Resultados!$E$2:$E$2000,$A62,Resultados!$H$2:$H$2000,G$58) | H62: =COUNTIFS(Resultados!$E$2:$E$2000,$A62,Resultados!$H$2:$H$2000,H$58) | I62: =IFERROR(SUMIFS(Resultados!$J$2:$J$2000,Resultados!$E$2:$E$2000,$A62)/COUNTIFS(Resultados!$E$2:$E$2000,$A62,Resultados!$J$2:$J$2000,">=0"),"")
...

Sheet Resultados
A1: Componente | B1: Tipo | C1: Regla | D1: Título de la regla | E1: Categoría | F1: Nivel | G1: Método | H1: Estado | I1: Severidad | J1: Puntaje | K1: Evidencia (archivo:línea — detalle) | L1: Observación | M1: Recomendación | N1: Responsable | O1: Fecha compromiso | P1: Estado de remediación
A2: web-fideinexus | B2: frontend | C2: SEC-002 | D2: Protocolo OIDC sobre OAuth 2.0 | E2: Identidad y autenticación | F2: DEBE | G2: Estático | H2: NO_CUMPLE | I2: Alta | J2: =IFERROR(IF(ISNUMBER(VLOOKUP(H2,Referencia!$A$5:$C$10,3,FALSE)),VLOOKUP(H2,Referencia!$A$5:$C$10,3,FALSE),""),"") | K2: src/app/core/services/auth.service.ts:29 — El login del frontend usa el grant_type=password (Resource Owner Password Credentials) contra /protocol/openid-connect/token, no Authorization Code + PKCE. | L2: El estandar exige Authorization Code con PKCE (S256) en el cliente publico y prohibe el flujo de password. Correccion: migrar el login a keycloak-js/oidc-client con responseType 'code' y pkceMethod 'S256' (el realm ya tiene el cliente publico prs-frontend). | M2: Migrar el login del frontend a Authorization Code con PKCE (keycloak-js u oidc-client) y desactivar el grant por password del cliente publico en Keycloak. | P2: Abierto
A3: web-fideinexus | B3: frontend | C3: SEC-004 | D3: Validación de tokens JWT | E3: Identidad y autenticación | F3: DEBE | G3: Mixto | H3: PARCIAL | I3: Crítica | J3: =IFERROR(IF(ISNUMBER(VLOOKUP(H3,Referencia!$A$5:$C$10,3,FALSE)),VLOOKUP(H3,Referencia!$A$5:$C$10,3,FALSE),""),"") | K3: src/app/core/services/auth.service.ts:135 — El frontend solo decodifica el JWT (jwt-decode) para leer el tenant y los roles; no firma ni valida la firma: eso lo hace cada microservicio. | L3: La validacion criptografica esta en el backend (resource server); el frontend solo lee claims, que es lo correcto para una SPA. | M3: No es un fallo del frontend: la validacion criptografica corresponde al backend. Documentar que el frontend solo lee claims. | P3: Abierto
A4: web-fideinexus | B4: frontend | C4: SEC-005 | D4: Autorización en backend | E4: Autorización y roles | F4: DEBE | G4: Estático | H4: PARCIAL | I4: Crítica | J4: =IFERROR(IF(ISNUMBER(VLOOKUP(H4,Referencia!$A$5:$C$10,3,FALSE)),VLOOKUP(H4,Referencia!$A$5:$C$10,3,FALSE),""),"") | K4: src/app/core/guards/auth.guard.ts:10 — El frontend tiene guard de autenticacion y de tenant, y oculta acciones por rol (canManage/canApprove). | L4: Es una capa de UX: la autorizacion real esta en los microservicios (SEC-005 de cada microservicio, CUMPLE). | M4: Correcto: es una capa de UX. La autorizacion real esta en cada microservicio (ver SEC-005 de los microservicios). | P4: Abierto
A5: web-fideinexus | B5: frontend | C5: SEC-009 | D5: Filtro obligatorio por tenant en datos | E5: Aislamiento multi-tenant | F5: DEBE | G5: Estático | H5: PARCIAL | I5: Crítica | J5: =IFERROR(IF(ISNUMBER(VLOOKUP(H5,Referencia!$A$5:$C$10,3,FALSE)),VLOOKUP(H5,Referencia!$A$5:$C$10,3,FALSE),""),"") | K5: src/app/features/(tenant)/solicitudes/services/:0 — El frontend envia ?tenantId= en las lecturas, pero quien acota de verdad es el backend (SEC-009 de los microservicios: CUMPLE). | L5: El filtro real esta en el backend. | M5: Correcto: el filtro real esta en el backend; el frontend puede omitir el tenantId en las lecturas. | P5: Abierto
A6: web-fideinexus | B6: frontend | C6: SEC-020 | D6: Control de pertenencia sobre recursos | E6: Integridad transversal | F6: DEBE | G6: Mixto | H6: PARCIAL | I6: Crítica | J6: =IFERROR(IF(ISNUMBER(VLOOKUP(H6,Referencia!$A$5:$C$10,3,FALSE)),VLOOKUP(H6,Referencia!$A$5:$C$10,3,FALSE),""),"") | K6: src/app/core/guards/auth.guard.ts:20 — El guard valida la pertenencia de parroquia al navegar; el control de pertenencia del recurso se aplica en el backend. | L6: El control fuerte esta en el microservicio (SEC-020: CUMPLE). | M6: Correcto: el control fuerte de pertenencia esta en el microservicio (ver SEC-020). | P6: Abierto
A7: gateway | B7: gateway | C7: SEC-016 | D7: Validación de entrada | E7: Datos, secretos y configuración | F7: DEBE | G7: Mixto | H7: PARCIAL | I7: Alta | J7: =IFERROR(IF(ISNUMBER(VLOOKUP(H7,Referencia!$A$5:$C$10,3,FALSE)),VLOOKUP(H7,Referencia!$A$5:$C$10,3,FALSE),""),"") | K7: src/main/java/:0 — El gateway no valida el cuerpo de las peticiones: delega la validacion en el microservicio (que la tiene con @Valid). | L7: La validacion de formato vive en el microservicio, que es donde tiene el contrato. | M7: Correcto: el gateway no valida el cuerpo; la validacion de formato vive en el microservicio, que tiene el contrato. | P7: Abierto
A8: gateway | B8: gateway | C8: SEC-019 | D8: Auditoría de operaciones sensibles | E8: Errores, logs y auditoría | F8: DEBE | G8: Estático | H8: PARCIAL | I8: Media | J8: =IFERROR(IF(ISNUMBER(VLOOKUP(H8,Referencia!$A$5:$C$10,3,FALSE)),VLOOKUP(H8,Referencia!$A$5:$C$10,3,FALSE),""),"") | K8: src/main/java/:0 — El gateway no lleva bitacora de auditoria propia; el rastro queda en los microservicios. | L8: La auditoria vive en el dominio. | M8: Registrar actor, fecha, recurso y resultado en las operaciones sensibles (aprobacion, cambio de estado, eliminacion) mediante una bitacora o eventos de auditoria. | P8: Abierto
A9: web-fideinexus | B9: frontend | C9: SEC-019 | D9: Auditoría de operaciones sensibles | E9: Errores, logs y auditoría | F9: DEBE | G9: Estático | H9: PARCIAL | I9: Media | J9: =IFERROR(IF(ISNUMBER(VLOOKUP(H9,Referencia!$A$5:$C$10,3,FALSE)),VLOOKUP(H9,Referencia!$A$5:$C$10,3,FALSE),""),"") | K9: src/app/features/(tenant)/solicitudes/components/solicitud-list/solicitud-list.ts:282 — La UI muestra avisos de exito/error, pero no hay bitacora de auditoria de las acciones del usuario (quien aprobo, quien elimino). | L9: El rastro de auditoria depende de los microservicios (created_at/updated_at y signed_by_user_id). | M9: Registrar actor, fecha, recurso y resultado en las operaciones sensibles (aprobacion, cambio de estado, eliminacion) mediante una bitacora o eventos de auditoria. | P9: Abierto
A10: web-fideinexus | B10: frontend | C10: SEC-022 | D10: Idempotencia y control de concurrencia | E10: Integridad transversal | F10: DEBERÍA | G10: Mixto | H10: PARCIAL | I10: Media | J10: =IFERROR(IF(ISNUMBER(VLOOKUP(H10,Referencia!$A$5:$C$10,3,FALSE)),VLOOKUP(H10,Referencia!$A$5:$C$10,3,FALSE),""),"") | K10: src/app/features/(tenant)/solicitudes/components/solicitud-form/solicitud-form.ts:603 — El formulario bloquea el doble submit (saveInProgress) pero no hay clave de idempotencia en el alta. | L10: Se evita el doble click, pero un reintento de red podria duplicar la solicitud. | M10: Agregar una clave de idempotencia (Idempotency-Key) o una restriccion UNIQUE por clave natural en el alta de solicitudes y participantes. | P10: Abierto
A11: svc-celebration | B11: microservicio | C11: SEC-015 | D11: Transporte seguro (HTTPS/TLS) | E11: Datos, secretos y configuración | F11: DEBE | G11: Mixto | H11: REQUIERE_REVISION_MANUAL | J11: =IFERROR(IF(ISNUMBER(VLOOKUP(H11,Referencia!$A$5:$C$10,3,FALSE)),VLOOKUP(H11,Referencia!$A$5:$C$10,3,FALSE),""),"") | K11: src/main/resources/application.yml:23 — La URL de la base y los emisores llegan por variables de entorno; el valor de produccion no es inspeccionable desde el repositorio | L11: La configuracion productiva (URLs https, TLS de la BD) se inyecta en el despliegue y no se pudo verificar desde el codigo. | M11: Confirmar en el despliegue de produccion que la URL de la base lleva sslmode=require y que el IdP se sirve por https.
A12: svc-certificate | B12: microservicio | C12: SEC-015 | D12: Transporte seguro (HTTPS/TLS) | E12: Datos, secretos y configuración | F12: DEBE | G12: Mixto | H12: REQUIERE_REVISION_MANUAL | J12: =IFERROR(IF(ISNUMBER(VLOOKUP(H12,Referencia!$A$5:$C$10,3,FALSE)),VLOOKUP(H12,Referencia!$A$5:$C$10,3,FALSE),""),"") | K12: src/main/resources/application.yml:23 — La URL de la base y los emisores llegan por variables de entorno; el valor de produccion no es inspeccionable desde el repositorio | L12: La configuracion productiva (URLs https, TLS de la BD) se inyecta en el despliegue y no se pudo verificar desde el codigo. | M12: Confirmar en el despliegue de produccion que la URL de la base lleva sslmode=require y que el IdP se sirve por https.
A13: svc-preparation | B13: microservicio | C13: SEC-015 | D13: Transporte seguro (HTTPS/TLS) | E13: Datos, secretos y configuración | F13: DEBE | G13: Mixto | H13: REQUIERE_REVISION_MANUAL | J13: =IFERROR(IF(ISNUMBER(VLOOKUP(H13,Referencia!$A$5:$C$10,3,FALSE)),VLOOKUP(H13,Referencia!$A$5:$C$10,3,FALSE),""),"") | K13: src/main/resources/application.yml:23 — La URL de la base y los emisores llegan por variables de entorno; el valor de produccion no es inspeccionable desde el repositorio | L13: La configuracion productiva (URLs https, TLS de la BD) se inyecta en el despliegue y no se pudo verificar desde el codigo. | M13: Confirmar en el despliegue de produccion que la URL de la base lleva sslmode=require y que el IdP se sirve por https.
A14: svc-requests | B14: microservicio | C14: SEC-015 | D14: Transporte seguro (HTTPS/TLS) | E14: Datos, secretos y configuración | F14: DEBE | G14: Mixto | H14: REQUIERE_REVISION_MANUAL | J14: =IFERROR(IF(ISNUMBER(VLOOKUP(H14,Referencia!$A$5:$C$10,3,FALSE)),VLOOKUP(H14,Referencia!$A$5:$C$10,3,FALSE),""),"") | K14: src/main/resources/application.yml:23 — La URL de la base y los emisores llegan por variables de entorno; el valor de produccion no es inspeccionable desde el repositorio | L14: La configuracion productiva (URLs https, TLS de la BD) se inyecta en el despliegue y no se pudo verificar desde el codigo. | M14: Confirmar en el despliegue de produccion que la URL de la base lleva sslmode=require y que el IdP se sirve por https.
A15: gateway | B15: gateway | C15: SEC-001 | D15: Proveedor de identidad | E15: Identidad y autenticación | F15: DEBE | G15: Mixto | H15: CUMPLE | J15: =IFERROR(IF(ISNUMBER(VLOOKUP(H15,Referencia!$A$5:$C$10,3,FALSE)),VLOOKUP(H15,Referencia!$A$5:$C$10,3,FALSE),""),"") | K15: src/main/resources/application-dev.yml:0 — El gateway valida los tokens contra el realm de Keycloak del ambiente (issuer-uri/jwk-set-uri por variable de entorno). | L15: IdP centralizado.
A16: svc-celebration | B16: microservicio | C16: SEC-001 | D16: Proveedor de identidad | E16: Identidad y autenticación | F16: DEBE | G16: Mixto | H16: CUMPLE | J16: =IFERROR(IF(ISNUMBER(VLOOKUP(H16,Referencia!$A$5:$C$10,3,FALSE)),VLOOKUP(H16,Referencia!$A$5:$C$10,3,FALSE),""),"") | K16: src/main/resources/application.yml:44 — issuer-uri: ${IDP_ISSUER_URI} (Keycloak por variable de ambiente) src/main/resources/application.yml:45 — jwk-set-uri: ${IDP_JWK_SET_URI} | L16: El IdP es Keycloak y la configuracion esta separada por ambiente (variables de entorno por perfil).
A17: svc-certificate | B17: microservicio | C17: SEC-001 | D17: Proveedor de identidad | E17: Identidad y autenticación | F17: DEBE | G17: Mixto | H17: CUMPLE | J17: =IFERROR(IF(ISNUMBER(VLOOKUP(H17,Referencia!$A$5:$C$10,3,FALSE)),VLOOKUP(H17,Referencia!$A$5:$C$10,3,FALSE),""),"") | K17: src/main/resources/application.yml:44 — issuer-uri: ${IDP_ISSUER_URI} (Keycloak por variable de ambiente) src/main/resources/application.yml:45 — jwk-set-uri: ${IDP_JWK_SET_URI} | L17: El IdP es Keycloak y la configuracion esta separada por ambiente (variables de entorno por perfil).
A18: svc-preparation | B18: microservicio | C18: SEC-001 | D18: Proveedor de identidad | E18: Identidad y autenticación | F18: DEBE | G18: Mixto | H18: CUMPLE | J18: =IFERROR(IF(ISNUMBER(VLOOKUP(H18,Referencia!$A$5:$C$10,3,FALSE)),VLOOKUP(H18,Referencia!$A$5:$C$10,3,FALSE),""),"") | K18: src/main/resources/application.yml:44 — issuer-uri: ${IDP_ISSUER_URI} (Keycloak por variable de ambiente) src/main/resources/application.yml:45 — jwk-set-uri: ${IDP_JWK_SET_URI} | L18: El IdP es Keycloak y la configuracion esta separada por ambiente (variables de entorno por perfil).
A19: svc-requests | B19: microservicio | C19: SEC-001 | D19: Proveedor de identidad | E19: Identidad y autenticación | F19: DEBE | G19: Mixto | H19: CUMPLE | J19: =IFERROR(IF(ISNUMBER(VLOOKUP(H19,Referencia!$A$5:$C$10,3,FALSE)),VLOOKUP(H19,Referencia!$A$5:$C$10,3,FALSE),""),"") | K19: src/main/resources/application.yml:44 — issuer-uri: ${IDP_ISSUER_URI} (Keycloak por variable de ambiente) src/main/resources/application.yml:45 — jwk-set-uri: ${IDP_JWK_SET_URI} | L19: El IdP es Keycloak y la configuracion esta separada por ambiente (variables de entorno por perfil).
A20: web-fideinexus | B20: frontend | C20: SEC-001 | D20: Proveedor de identidad | E20: Identidad y autenticación | F20: DEBE | G20: Mixto | H20: CUMPLE | J20: =IFERROR(IF(ISNUMBER(VLOOKUP(H20,Referencia!$A$5:$C$10,3,FALSE)),VLOOKUP(H20,Referencia!$A$5:$C$10,3,FALSE),""),"") | K20: src/app/core/services/auth.service.ts:12 — El frontend apunta al realm de Keycloak del ambiente (https://lab.vallegrande.edu.pe/keycloak-security/realms/prs-realm) leido de una constante de environment; la URL del IdP esta separada por ambiente. | L20: Keycloak como IdP centralizado.
A21: gateway | B21: gateway | C21: SEC-002 | D21: Protocolo OIDC sobre OAuth 2.0 | E21: Identidad y autenticación | F21: DEBE | G21: Estático | H21: CUMPLE | J21: =IFERROR(IF(ISNUMBER(VLOOKUP(H21,Referencia!$A$5:$C$10,3,FALSE)),VLOOKUP(H21,Referencia!$A$5:$C$10,3,FALSE),""),"") | K21: src/main/java/:0 — El gateway no gestiona contrasenas de usuarios: solo valida y propaga el JWT. | L21: n/a en el gateway.
A22: svc-celebration | B22: microservicio | C22: SEC-002 | D22: Protocolo OIDC sobre OAuth 2.0 | E22: Identidad y autenticación | F22: DEBE | G22: Estático | H22: CUMPLE | J22: =IFERROR(IF(ISNUMBER(VLOOKUP(H22,Referencia!$A$5:$C$10,3,FALSE)),VLOOKUP(H22,Referencia!$A$5:$C$10,3,FALSE),""),"") | K22: src/main/resources/application.yml:44 — No existe ningun endpoint de login en el microservicio: es resource server y no toca contrasenas | L22: El backend no gestiona contrasenas de usuarios finales; el unico login propio esta en el frontend (ver SEC-002 del componente web).
A23: svc-certificate | B23: microservicio | C23: SEC-002 | D23: Protocolo OIDC sobre OAuth 2.0 | E23: Identidad y autenticación | F23: DEBE | G23: Estático | H23: CUMPLE | J23: =IFERROR(IF(ISNUMBER(VLOOKUP(H23,Referencia!$A$5:$C$10,3,FALSE)),VLOOKUP(H23,Referencia!$A$5:$C$10,3,FALSE),""),"") | K23: src/main/resources/application.yml:44 — No existe ningun endpoint de login en el microservicio: es resource server y no toca contrasenas | L23: El backend no gestiona contrasenas de usuarios finales; el unico login propio esta en el frontend (ver SEC-002 del componente web).
A24: svc-preparation | B24: microservicio | C24: SEC-002 | D24: Protocolo OIDC sobre OAuth 2.0 | E24: Identidad y autenticación | F24: DEBE | G24: Estático | H24: CUMPLE | J24: =IFERROR(IF(ISNUMBER(VLOOKUP(H24,Referencia!$A$5:$C$10,3,FALSE)),VLOOKUP(H24,Referencia!$A$5:$C$10,3,FALSE),""),"") | K24: src/main/resources/application.yml:44 — No existe ningun endpoint de login en el microservicio: es resource server y no toca contrasenas | L24: El backend no gestiona contrasenas de usuarios finales; el unico login propio esta en el frontend (ver SEC-002 del componente web).
A25: svc-requests | B25: microservicio | C25: SEC-002 | D25: Protocolo OIDC sobre OAuth 2.0 | E25: Identidad y autenticación | F25: DEBE | G25: Estático | H25: CUMPLE | J25: =IFERROR(IF(ISNUMBER(VLOOKUP(H25,Referencia!$A$5:$C$10,3,FALSE)),VLOOKUP(H25,Referencia!$A$5:$C$10,3,FALSE),""),"") | K25: src/main/resources/application.yml:44 — No existe ningun endpoint de login en el microservicio: es resource server y no toca contrasenas | L25: El backend no gestiona contrasenas de usuarios finales; el unico login propio esta en el frontend (ver SEC-002 del componente web).
A26: gateway | B26: gateway | C26: SEC-003 | D26: Clientes de Keycloak por responsabilidad | E26: Identidad y autenticación | F26: DEBE | G26: Estático | H26: CUMPLE | J26: =IFERROR(IF(ISNUMBER(VLOOKUP(H26,Referencia!$A$5:$C$10,3,FALSE)),VLOOKUP(H26,Referencia!$A$5:$C$10,3,FALSE),""),"") | K26: src/main/resources/application-dev.yml:0 — El gateway no usa client_secret; enruta el token del cliente al microservicio destino. | L26: Sin secretos de cliente.
... A90: gateway | B90: gateway | C90: SEC-017 | D90: Respuestas de error diferenciadas y seguras | E90: Errores, logs y auditoría | F90: DEBE | G90: Mixto | H90: CUMPLE | J90: =IFERROR(IF(ISNUMBER(VLOOKUP(H90,Referencia!$A$5:$C$10,3,FALSE)),VLOOKUP(H90,Referencia!$A$5:$C$10,3,FALSE),""),"") | K90: src/main/java/:0 — Los errores del destino se devuelven con su codigo y sin stack traces. | L90: Errores sin fuga de informacion.
A91: svc-celebration | B91: microservicio | C91: SEC-017 | D91: Respuestas de error diferenciadas y seguras | E91: Errores, logs y auditoría | F91: DEBE | G91: Mixto | H91: CUMPLE | J91: =IFERROR(IF(ISNUMBER(VLOOKUP(H91,Referencia!$A$5:$C$10,3,FALSE)),VLOOKUP(H91,Referencia!$A$5:$C$10,3,FALSE),""),"") | K91: src/main/java/pe/edu/vallegrande/fideinexus/requests/infrastructure/exception/GlobalExceptionHandler.java:29 — Los errores de validacion (WebExchangeBindException, IllegalArgumentException) se devuelven con 422 UNPROCESSABLE_ENTITY; 404 para lo inexistente, 403 sin permiso y 409 para conflictos, sin stack traces. | L91: 401/403/404/409/422 diferenciados y sin fuga de informacion. | M91: Ninguna: el control esta implementado y verificado.
A92: svc-certificate | B92: microservicio | C92: SEC-017 | D92: Respuestas de error diferenciadas y seguras | E92: Errores, logs y auditoría | F92: DEBE | G92: Mixto | H92: CUMPLE | J92: =IFERROR(IF(ISNUMBER(VLOOKUP(H92,Referencia!$A$5:$C$10,3,FALSE)),VLOOKUP(H92,Referencia!$A$5:$C$10,3,FALSE),""),"") | K92: src/main/java/pe/edu/vallegrande/fideinexus/requests/infrastructure/exception/GlobalExceptionHandler.java:29 — Los errores de validacion (WebExchangeBindException, IllegalArgumentException) se devuelven con 422 UNPROCESSABLE_ENTITY; 404 para lo inexistente, 403 sin permiso y 409 para conflictos, sin stack traces. | L92: 401/403/404/409/422 diferenciados y sin fuga de informacion. | M92: Ninguna: el control esta implementado y verificado.
A93: svc-preparation | B93: microservicio | C93: SEC-017 | D93: Respuestas de error diferenciadas y seguras | E93: Errores, logs y auditoría | F93: DEBE | G93: Mixto | H93: CUMPLE | J93: =IFERROR(IF(ISNUMBER(VLOOKUP(H93,Referencia!$A$5:$C$10,3,FALSE)),VLOOKUP(H93,Referencia!$A$5:$C$10,3,FALSE),""),"") | K93: src/main/java/pe/edu/vallegrande/fideinexus/requests/infrastructure/exception/GlobalExceptionHandler.java:29 — Los errores de validacion (WebExchangeBindException, IllegalArgumentException) se devuelven con 422 UNPROCESSABLE_ENTITY; 404 para lo inexistente, 403 sin permiso y 409 para conflictos, sin stack traces. | L93: 401/403/404/409/422 diferenciados y sin fuga de informacion. | M93: Ninguna: el control esta implementado y verificado.
A94: svc-requests | B94: microservicio | C94: SEC-017 | D94: Respuestas de error diferenciadas y seguras | E94: Errores, logs y auditoría | F94: DEBE | G94: Mixto | H94: CUMPLE | J94: =IFERROR(IF(ISNUMBER(VLOOKUP(H94,Referencia!$A$5:$C$10,3,FALSE)),VLOOKUP(H94,Referencia!$A$5:$C$10,3,FALSE),""),"") | K94: src/main/java/pe/edu/vallegrande/fideinexus/requests/infrastructure/exception/GlobalExceptionHandler.java:29 — Los errores de validacion (WebExchangeBindException, IllegalArgumentException) se devuelven con 422 UNPROCESSABLE_ENTITY; 404 para lo inexistente, 403 sin permiso y 409 para conflictos, sin stack traces. | L94: 401/403/404/409/422 diferenciados y sin fuga de informacion. | M94: Ninguna: el control esta implementado y verificado.
A95: web-fideinexus | B95: frontend | C95: SEC-017 | D95: Respuestas de error diferenciadas y seguras | E95: Errores, logs y auditoría | F95: DEBE | G95: Mixto | H95: CUMPLE | J95: =IFERROR(IF(ISNUMBER(VLOOKUP(H95,Referencia!$A$5:$C$10,3,FALSE)),VLOOKUP(H95,Referencia!$A$5:$C$10,3,FALSE),""),"") | K95: src/app/features/(tenant)/solicitudes/components/solicitud-detail/solicitud-detail.ts:700 — El frontend distingue 403 (sin permiso) y 404 (no encontrado) y muestra mensajes claros sin volcar la respuesta cruda. | L95: Errores claros para el usuario.
A96: gateway | B96: gateway | C96: SEC-018 | D96: Logs seguros | E96: Errores, logs y auditoría | F96: DEBE | G96: Mixto | H96: CUMPLE | J96: =IFERROR(IF(ISNUMBER(VLOOKUP(H96,Referencia!$A$5:$C$10,3,FALSE)),VLOOKUP(H96,Referencia!$A$5:$C$10,3,FALSE),""),"") | K96: src/main/java/:0 — No se loguean tokens ni credenciales. | L96: Logs seguros.
A97: svc-celebration | B97: microservicio | C97: SEC-018 | D97: Logs seguros | E97: Errores, logs y auditoría | F97: DEBE | G97: Mixto | H97: CUMPLE | J97: =IFERROR(IF(ISNUMBER(VLOOKUP(H97,Referencia!$A$5:$C$10,3,FALSE)),VLOOKUP(H97,Referencia!$A$5:$C$10,3,FALSE),""),"") | K97: src/main/java/pe/edu/vallegrande/fideinexus/celebration/infrastructure/exception/GlobalExceptionHandler.java:52 — El log de error lleva metodo y ruta; no se registran tokens ni cuerpos de peticion | L97: Los logs no contienen datos sensibles.
A98: svc-certificate | B98: microservicio | C98: SEC-018 | D98: Logs seguros | E98: Errores, logs y auditoría | F98: DEBE | G98: Mixto | H98: CUMPLE | J98: =IFERROR(IF(ISNUMBER(VLOOKUP(H98,Referencia!$A$5:$C$10,3,FALSE)),VLOOKUP(H98,Referencia!$A$5:$C$10,3,FALSE),""),"") | K98: src/main/java/pe/edu/vallegrande/fideinexus/certificate/infrastructure/exception/GlobalExceptionHandler.java:52 — El log de error lleva metodo y ruta; no se registran tokens ni cuerpos de peticion | L98: Los logs no contienen datos sensibles.
A99: svc-preparation | B99: microservicio | C99: SEC-018 | D99: Logs seguros | E99: Errores, logs y auditoría | F99: DEBE | G99: Mixto | H99: CUMPLE | J99: =IFERROR(IF(ISNUMBER(VLOOKUP(H99,Referencia!$A$5:$C$10,3,FALSE)),VLOOKUP(H99,Referencia!$A$5:$C$10,3,FALSE),""),"") | K99: src/main/java/pe/edu/vallegrande/fideinexus/preparation/infrastructure/exception/GlobalExceptionHandler.java:52 — El log de error lleva metodo y ruta; no se registran tokens ni cuerpos de peticion | L99: Los logs no contienen datos sensibles.
A100: svc-requests | B100: microservicio | C100: SEC-018 | D100: Logs seguros | E100: Errores, logs y auditoría | F100: DEBE | G100: Mixto | H100: CUMPLE | J100: =IFERROR(IF(ISNUMBER(VLOOKUP(H100,Referencia!$A$5:$C$10,3,FALSE)),VLOOKUP(H100,Referencia!$A$5:$C$10,3,FALSE),""),"") | K100: src/main/java/pe/edu/vallegrande/fideinexus/requests/infrastructure/exception/GlobalExceptionHandler.java:52 — El log de error lleva metodo y ruta; no se registran tokens ni cuerpos de peticion | L100: Los logs no contienen datos sensibles.
A101: web-fideinexus | B101: frontend | C101: SEC-018 | D101: Logs seguros | E101: Errores, logs y auditoría | F101: DEBE | G101: Mixto | H101: CUMPLE | J101: =IFERROR(IF(ISNUMBER(VLOOKUP(H101,Referencia!$A$5:$C$10,3,FALSE)),VLOOKUP(H101,Referencia!$A$5:$C$10,3,FALSE),""),"") | K101: src/app/core/services/auth.service.ts:51 — El token se guarda en localStorage y no se imprime en consola: git grep 'console.log' no encuentra volados de token en el modulo. | L101: No se loguean tokens.
A102: svc-celebration | B102: microservicio | C102: SEC-019 | D102: Auditoría de operaciones sensibles | E102: Errores, logs y auditoría | F102: DEBE | G102: Estático | H102: CUMPLE | J102: =IFERROR(IF(ISNUMBER(VLOOKUP(H102,Referencia!$A$5:$C$10,3,FALSE)),VLOOKUP(H102,Referencia!$A$5:$C$10,3,FALSE),""),"") | K102: src/main/java/pe/edu/vallegrande/fideinexus/requests/application/usecase/ServiceManagementService.java:126 — auditar(...) registra cada operacion sensible (CREATE, UPDATE, STATUS, DELETE) en la tabla audit_log con tenant, actor (correo del token), accion, entidad, id del recurso, resultado y fecha. src/main/resources/sql/schema.sql:1 — Tabla audit_log con indice por tenant y fecha. | L102: Verificado en runtime: las operaciones dejan actor, fecha, recurso y resultado. | M102: Ninguna: el control esta implementado y verificado.
A103: svc-certificate | B103: microservicio | C103: SEC-019 | D103: Auditoría de operaciones sensibles | E103: Errores, logs y auditoría | F103: DEBE | G103: Estático | H103: CUMPLE | J103: =IFERROR(IF(ISNUMBER(VLOOKUP(H103,Referencia!$A$5:$C$10,3,FALSE)),VLOOKUP(H103,Referencia!$A$5:$C$10,3,FALSE),""),"") | K103: src/main/java/pe/edu/vallegrande/fideinexus/requests/application/usecase/ServiceManagementService.java:126 — auditar(...) registra cada operacion sensible (CREATE, UPDATE, STATUS, DELETE) en la tabla audit_log con tenant, actor (correo del token), accion, entidad, id del recurso, resultado y fecha. src/main/resources/sql/schema.sql:1 — Tabla audit_log con indice por tenant y fecha. | L103: Verificado en runtime: las operaciones dejan actor, fecha, recurso y resultado. | M103: Ninguna: el control esta implementado y verificado.
...

Sheet Pruebas y checklist
A1: Checklist para revisión (sección 12 del estándar)
A2: Estado calculado con fórmulas a partir de las reglas y pruebas vinculadas. Peor resultado manda: cualquier NO_CUMPLE → NO CUMPLE.
A4: # | B4: Ítem del checklist | C4: Reglas / pruebas vinculadas | D4: Estado | E4: Comentario del revisor
A5: 1 | B5: Keycloak está configurado por ambiente. | C5: SEC-001 | D5: =IF(COUNTIFS(Resultados!$C$2:$C$2000,"SEC-001",Resultados!$H$2:$H$2000,"NO_CUMPLE")>0,"NO CUMPLE",IF(COUNTIFS(Resultados!$C$2:$C$2000,"SEC-001",Resultados!$H$2:$H$2000,"PARCIAL")+COUNTIFS(Resultados!$C$2:$C$2000,"SEC-001",Resultados!$H$2:$H$2000,"REQUIERE_REVISION_MANUAL")+COUNTIFS(Resultados!$C$2:$C$2000,"SEC-001",Resultados!$H$2:$H$2000,"SIN_EVALUAR")>0,"PARCIAL / PENDIENTE",IF(COUNTIFS(Resultados!$C$2:$C$2000,"SEC-001",Resultados!$H$2:$H$2000,"CUMPLE")>0,"CUMPLE","SIN DATOS")))
A6: 2 | B6: Los clientes tienen responsabilidades separadas. | C6: SEC-003 | D6: =IF(COUNTIFS(Resultados!$C$2:$C$2000,"SEC-003",Resultados!$H$2:$H$2000,"NO_CUMPLE")>0,"NO CUMPLE",IF(COUNTIFS(Resultados!$C$2:$C$2000,"SEC-003",Resultados!$H$2:$H$2000,"PARCIAL")+COUNTIFS(Resultados!$C$2:$C$2000,"SEC-003",Resultados!$H$2:$H$2000,"REQUIERE_REVISION_MANUAL")+COUNTIFS(Resultados!$C$2:$C$2000,"SEC-003",Resultados!$H$2:$H$2000,"SIN_EVALUAR")>0,"PARCIAL / PENDIENTE",IF(COUNTIFS(Resultados!$C$2:$C$2000,"SEC-003",Resultados!$H$2:$H$2000,"CUMPLE")>0,"CUMPLE","SIN DATOS")))
A7: 3 | B7: El JWT se valida en backend. | C7: SEC-004 | D7: =IF(COUNTIFS(Resultados!$C$2:$C$2000,"SEC-004",Resultados!$H$2:$H$2000,"NO_CUMPLE")>0,"NO CUMPLE",IF(COUNTIFS(Resultados!$C$2:$C$2000,"SEC-004",Resultados!$H$2:$H$2000,"PARCIAL")+COUNTIFS(Resultados!$C$2:$C$2000,"SEC-004",Resultados!$H$2:$H$2000,"REQUIERE_REVISION_MANUAL")+COUNTIFS(Resultados!$C$2:$C$2000,"SEC-004",Resultados!$H$2:$H$2000,"SIN_EVALUAR")>0,"PARCIAL / PENDIENTE",IF(COUNTIFS(Resultados!$C$2:$C$2000,"SEC-004",Resultados!$H$2:$H$2000,"CUMPLE")>0,"CUMPLE","SIN DATOS")))
A8: 4 | B8: Los endpoints tienen autorización por rol. | C8: SEC-005, SEC-007 | D8: =IF(COUNTIFS(Resultados!$C$2:$C$2000,"SEC-005",Resultados!$H$2:$H$2000,"NO_CUMPLE")+COUNTIFS(Resultados!$C$2:$C$2000,"SEC-007",Resultados!$H$2:$H$2000,"NO_CUMPLE")>0,"NO CUMPLE",IF(COUNTIFS(Resultados!$C$2:$C$2000,"SEC-005",Resultados!$H$2:$H$2000,"PARCIAL")+COUNTIFS(Resultados!$C$2:$C$2000,"SEC-005",Resultados!$H$2:$H$2000,"REQUIERE_REVISION_MANUAL")+COUNTIFS(Resultados!$C$2:$C$2000,"SEC-005",Resultados!$H$2:$H$2000,"SIN_EVALUAR")+COUNTIFS(Resultados!$C$2:$C$2000,"SEC-007",Resultados!$H$2:$H$2000,"PARCIAL")+COUNTIFS(Resultados!$C$2:$C$2000,"SEC-007",Resultados!$H$2:$H$2000,"REQUIERE_REVISION_MANUAL")+COUNTIFS(Resultados!$C$2:$C$2000,"SEC-007",Resultados!$H$2:$H$2000,"SIN_EVALUAR")>0,"PARCIAL / PENDIENTE",IF(COUNTIFS(Resultados!$C$2:$C$2000,"SEC-005",Resultados!$H$2:$H$2000,"CUMPLE")+COUNTIFS(Resultados!$C$2:$C$2000,"SEC-007",Resultados!$H$2:$H$2000,"CUMPLE")>0,"CUMPLE","SIN DATOS")))
A9: 5 | B9: El tenant se obtiene y valida desde un contexto confiable. | C9: SEC-008 | D9: =IF(COUNTIFS(Resultados!$C$2:$C$2000,"SEC-008",Resultados!$H$2:$H$2000,"NO_CUMPLE")>0,"NO CUMPLE",IF(COUNTIFS(Resultados!$C$2:$C$2000,"SEC-008",Resultados!$H$2:$H$2000,"PARCIAL")+COUNTIFS(Resultados!$C$2:$C$2000,"SEC-008",Resultados!$H$2:$H$2000,"REQUIERE_REVISION_MANUAL")+COUNTIFS(Resultados!$C$2:$C$2000,"SEC-008",Resultados!$H$2:$H$2000,"SIN_EVALUAR")>0,"PARCIAL / PENDIENTE",IF(COUNTIFS(Resultados!$C$2:$C$2000,"SEC-008",Resultados!$H$2:$H$2000,"CUMPLE")>0,"CUMPLE","SIN DATOS")))
A10: 6 | B10: Las consultas filtran por tenant y año lectivo cuando corresponde. | C10: SEC-009, SEC-021 | D10: =IF(COUNTIFS(Resultados!$C$2:$C$2000,"SEC-009",Resultados!$H$2:$H$2000,"NO_CUMPLE")+COUNTIFS(Resultados!$C$2:$C$2000,"SEC-021",Resultados!$H$2:$H$2000,"NO_CUMPLE")>0,"NO CUMPLE",IF(COUNTIFS(Resultados!$C$2:$C$2000,"SEC-009",Resultados!$H$2:$H$2000,"PARCIAL")+COUNTIFS(Resultados!$C$2:$C$2000,"SEC-009",Resultados!$H$2:$H$2000,"REQUIERE_REVISION_MANUAL")+COUNTIFS(Resultados!$C$2:$C$2000,"SEC-009",Resultados!$H$2:$H$2000,"SIN_EVALUAR")+COUNTIFS(Resultados!$C$2:$C$2000,"SEC-021",Resultados!$H$2:$H$2000,"PARCIAL")+COUNTIFS(Resultados!$C$2:$C$2000,"SEC-021",Resultados!$H$2:$H$2000,"REQUIERE_REVISION_MANUAL")+COUNTIFS(Resultados!$C$2:$C$2000,"SEC-021",Resultados!$H$2:$H$2000,"SIN_EVALUAR")>0,"PARCIAL / PENDIENTE",IF(COUNTIFS(Resultados!$C$2:$C$2000,"SEC-009",Resultados!$H$2:$H$2000,"CUMPLE")+COUNTIFS(Resultados!$C$2:$C$2000,"SEC-021",Resultados!$H$2:$H$2000,"CUMPLE")>0,"CUMPLE","SIN DATOS")))
A11: 7 | B11: No existen secretos en el repositorio. | C11: SEC-014 | D11: =IF(COUNTIFS(Resultados!$C$2:$C$2000,"SEC-014",Resultados!$H$2:$H$2000,"NO_CUMPLE")>0,"NO CUMPLE",IF(COUNTIFS(Resultados!$C$2:$C$2000,"SEC-014",Resultados!$H$2:$H$2000,"PARCIAL")+COUNTIFS(Resultados!$C$2:$C$2000,"SEC-014",Resultados!$H$2:$H$2000,"REQUIERE_REVISION_MANUAL")+COUNTIFS(Resultados!$C$2:$C$2000,"SEC-014",Resultados!$H$2:$H$2000,"SIN_EVALUAR")>0,"PARCIAL / PENDIENTE",IF(COUNTIFS(Resultados!$C$2:$C$2000,"SEC-014",Resultados!$H$2:$H$2000,"CUMPLE")>0,"CUMPLE","SIN DATOS")))
A12: 8 | B12: Los errores no revelan información sensible. | C12: SEC-017 | D12: =IF(COUNTIFS(Resultados!$C$2:$C$2000,"SEC-017",Resultados!$H$2:$H$2000,"NO_CUMPLE")>0,"NO CUMPLE",IF(COUNTIFS(Resultados!$C$2:$C$2000,"SEC-017",Resultados!$H$2:$H$2000,"PARCIAL")+COUNTIFS(Resultados!$C$2:$C$2000,"SEC-017",Resultados!$H$2:$H$2000,"REQUIERE_REVISION_MANUAL")+COUNTIFS(Resultados!$C$2:$C$2000,"SEC-017",Resultados!$H$2:$H$2000,"SIN_EVALUAR")>0,"PARCIAL / PENDIENTE",IF(COUNTIFS(Resultados!$C$2:$C$2000,"SEC-017",Resultados!$H$2:$H$2000,"CUMPLE")>0,"CUMPLE","SIN DATOS")))
A13: 9 | B13: Los logs no contienen tokens ni contraseñas. | C13: SEC-018 | D13: =IF(COUNTIFS(Resultados!$C$2:$C$2000,"SEC-018",Resultados!$H$2:$H$2000,"NO_CUMPLE")>0,"NO CUMPLE",IF(COUNTIFS(Resultados!$C$2:$C$2000,"SEC-018",Resultados!$H$2:$H$2000,"PARCIAL")+COUNTIFS(Resultados!$C$2:$C$2000,"SEC-018",Resultados!$H$2:$H$2000,"REQUIERE_REVISION_MANUAL")+COUNTIFS(Resultados!$C$2:$C$2000,"SEC-018",Resultados!$H$2:$H$2000,"SIN_EVALUAR")>0,"PARCIAL / PENDIENTE",IF(COUNTIFS(Resultados!$C$2:$C$2000,"SEC-018",Resultados!$H$2:$H$2000,"CUMPLE")>0,"CUMPLE","SIN DATOS")))
A14: 10 | B14: Existen pruebas de 401, 403, tenant incorrecto e idempotencia. | C14: T01, T03, T04, T07 | D14: =IF(COUNTIFS('Pruebas y checklist'!$A$22:$A$30,"T01",'Pruebas y checklist'!$E$22:$E$30,"NO_CUMPLE")+COUNTIFS('Pruebas y checklist'!$A$22:$A$30,"T03",'Pruebas y checklist'!$E$22:$E$30,"NO_CUMPLE")+COUNTIFS('Pruebas y checklist'!$A$22:$A$30,"T04",'Pruebas y checklist'!$E$22:$E$30,"NO_CUMPLE")+COUNTIFS('Pruebas y checklist'!$A$22:$A$30,"T07",'Pruebas y checklist'!$E$22:$E$30,"NO_CUMPLE")>0,"NO CUMPLE",IF(COUNTIFS('Pruebas y checklist'!$A$22:$A$30,"T01",'Pruebas y checklist'!$E$22:$E$30,"PARCIAL")+COUNTIFS('Pruebas y checklist'!$A$22:$A$30,"T01",'Pruebas y checklist'!$E$22:$E$30,"REQUIERE_REVISION_MANUAL")+COUNTIFS('Pruebas y checklist'!$A$22:$A$30,"T01",'Pruebas y checklist'!$E$22:$E$30,"SIN_EVALUAR")+COUNTIFS('Pruebas y checklist'!$A$22:$A$30,"T03",'Pruebas y checklist'!$E$22:$E$30,"PARCIAL")+COUNTIFS('Pruebas y checklist'!$A$22:$A$30,"T03",'Pruebas y checklist'!$E$22:$E$30,"REQUIERE_REVISION_MANUAL")+COUNTIFS('Pruebas y checklist'!$A$22:$A$30,"T03",'Pruebas y checklist'!$E$22:$E$30,"SIN_EVALUAR")+COUNTIFS('Pruebas y checklist'!$A$22:$A$30,"T04",'Pruebas y checklist'!$E$22:$E$30,"PARCIAL")+COUNTIFS('Pruebas y checklist'!$A$22:$A$30,"T04",'Pruebas y checklist'!$E$22:$E$30,"REQUIERE_REVISION_MANUAL")+COUNTIFS('Pruebas y checklist'!$A$22:$A$30,"T04",'Pruebas y checklist'!$E$22:$E$30,"SIN_EVALUAR")+COUNTIFS('Pruebas y checklist'!$A$22:$A$30,"T07",'Pruebas y checklist'!$E$22:$E$30,"PARCIAL")+COUNTIFS('Pruebas y checklist'!$A$22:$A$30,"T07",'Pruebas y checklist'!$E$22:$E$30,"REQUIERE_REVISION_MANUAL")+COUNTIFS('Pruebas y checklist'!$A$22:$A$30,"T07",'Pruebas y checklist'!$E$22:$E$30,"SIN_EVALUAR")>0,"PARCIAL / PENDIENTE",IF(COUNTIFS('Pruebas y checklist'!$A$22:$A$30,"T01",'Pruebas y checklist'!$E$22:$E$30,"CUMPLE")+COUNTIFS('Pruebas y checklist'!$A$22:$A$30,"T03",'Pruebas y checklist'!$E$22:$E$30,"CUMPLE")+COUNTIFS('Pruebas y checklist'!$A$22:$A$30,"T04",'Pruebas y checklist'!$E$22:$E$30,"CUMPLE")+COUNTIFS('Pruebas y checklist'!$A$22:$A$30,"T07",'Pruebas y checklist'!$E$22:$E$30,"CUMPLE")>0,"CUMPLE","SIN DATOS")))
A15: 11 | B15: La documentación y los roles coinciden con la configuración real. | C15: SEC-006 | D15: =IF(COUNTIFS(Resultados!$C$2:$C$2000,"SEC-006",Resultados!$H$2:$H$2000,"NO_CUMPLE")>0,"NO CUMPLE",IF(COUNTIFS(Resultados!$C$2:$C$2000,"SEC-006",Resultados!$H$2:$H$2000,"PARCIAL")+COUNTIFS(Resultados!$C$2:$C$2000,"SEC-006",Resultados!$H$2:$H$2000,"REQUIERE_REVISION_MANUAL")+COUNTIFS(Resultados!$C$2:$C$2000,"SEC-006",Resultados!$H$2:$H$2000,"SIN_EVALUAR")>0,"PARCIAL / PENDIENTE",IF(COUNTIFS(Resultados!$C$2:$C$2000,"SEC-006",Resultados!$H$2:$H$2000,"CUMPLE")>0,"CUMPLE","SIN DATOS")))
A16: 12 | B16: Las reglas se aplican de forma consistente en todos los proyectos. | C16: — | D16: REVISIÓN MANUAL
A19: Pruebas mínimas (sección 11 del estándar)
A20: Si no hay observación, la columna muestra cómo verificar la prueba. SIN_EVALUAR = prueba no ejecutada ni confirmada por pruebas automatizadas existentes.
A21: ID | B21: Prueba mínima | C21: Resultado esperado | D21: Reglas relacionadas | E21: Estado | F21: Método | G21: Componentes probados | H21: Evidencia | I21: Observación
A22: T01 | B22: Solicitud sin token | C22: Responde 401. | D22: SEC-004, SEC-017 | E22: REQUIERE_REVISION_MANUAL | F22: Estático | H22: src/main/resources/application.yml:44 — Resource server con issuer-uri: sin Authorization responde 401 | I22: No se ejecuto una peticion sin token contra los microservicios en esta auditoria.
A23: T02 | B23: Token vencido o con issuer incorrecto | C23: Responde 401. | D23: SEC-004 | E23: SIN_EVALUAR | I23: Prueba dinámica con un token expirado o emitido por otro realm. Estático: confirmar validadores de exp e iss y existencia de pruebas.
A24: T03 | B24: Usuario autenticado sin rol | C24: Responde 403. | D24: SEC-005, SEC-007 | E24: REQUIERE_REVISION_MANUAL | F24: Estático | H24: src/main/java/pe/edu/vallegrande/fideinexus/requests/infrastructure/adapter/in/rest/controller/ServiceRest.java:77 — hasAnyRole con SECRETARIO, PARROCO y SUPERADMIN | I24: Los roles se verificaron por codigo (@PreAuthorize) y en runtime durante la sesion (403 sin rol).
A25: T04 | B25: Usuario de otro tenant | C25: No puede leer ni modificar el recurso. | D25: SEC-008, SEC-009, SEC-010 | E25: CUMPLE | F25: Dinámico | H25: src/main/java/pe/edu/vallegrande/fideinexus/requests/infrastructure/adapter/in/rest/controller/ServiceRest.java:85 — ensureSameTenant / currentTenantId: 403 al cambiar de parroquia | I25: Verificado en runtime con tokens de dos parroquias: el tenant 10 recibe 403 al consultar recursos del tenant 9.
A26: T05 | B26: Docente intentando usar otra clase | C26: La operación es rechazada. | D26: SEC-020 | E26: SIN_EVALUAR | I26: Prueba dinámica con un docente y una clase ajena. Estático: verificación de relación docente-clase en servicio.
A27: T06 | B27: Token o secreto en logs o respuestas | C27: No aparece. | D27: SEC-014, SEC-017, SEC-018 | E27: SIN_EVALUAR | I27: Revisar logs de una ejecución de pruebas y respuestas de error; estático: búsqueda de logging de credenciales y trazas en respuestas.
A28: T07 | B28: Reintento de operación masiva | C28: No duplica datos. | D28: SEC-022 | E28: SIN_EVALUAR | I28: Prueba dinámica ejecutando dos veces la misma operación. Estático: claves de idempotencia, restricciones únicas, pruebas existentes.
A29: T08 | B29: CORS con origen no autorizado | C29: Se rechaza. | D29: SEC-013 | E29: SIN_EVALUAR | I29: Prueba dinámica con cabecera Origin no permitida. Estático: lista de orígenes por ambiente.
A30: T09 | B30: Datos inválidos con frontend manipulado | C30: El servicio los rechaza igualmente. | D30: SEC-016 | E30: SIN_EVALUAR | I30: Prueba dinámica enviando payloads inválidos directo al API. Estático: restricciones de validación en DTO y activación de @Valid.

Sheet Referencia
A1: Referencia: leyenda, método de cálculo y reglas del estándar
A3: Estados y peso en el cumplimiento
A4: Estado | C4: Peso | D4: Significado
A5: CUMPLE | C5: 1 | D5: Todas las verificaciones obligatorias de la regla tienen evidencia positiva.
A6: PARCIAL | C6: 0.5 | D6: Algunas verificaciones se cumplen y otras no, o se cumple solo en parte del componente.
A7: NO_CUMPLE | C7: 0 | D7: Hay evidencia de incumplimiento, o el control esperado no existe tras revisar el código relevante.
A8: NO_APLICA | C8: n/a | D8: La regla no aplica al componente; debe justificarse en la observación.
A9: REQUIERE_REVISION_MANUAL | C9: n/a | D9: No se puede decidir con el código disponible (configuración externa, prueba dinámica, decisión de negocio).
A10: SIN_EVALUAR | C10: n/a | D10: Estado automático del generador cuando una regla aplicable no tiene resultado.
A11: Los pesos en azul/amarillo son supuestos editables: PARCIAL=0.5 es una convención de este reporte, no del estándar.
A13: Niveles normativos del estándar
A14: DEBE | B14: Requisito obligatorio. Un NO_CUMPLE bloquea el veredicto.
A15: DEBERÍA | B15: Recomendación; solo puede omitirse con justificación.
A17: Notas de lectura
A18: • Celdas amarillas con texto azul = datos para completar (responsable, fecha, estado de remediación, comentarios, pesos).
A19: • Resumen y Checklist son fórmulas sobre la hoja Resultados; al corregir un estado se recalculan.
A20: • En Resultados las filas vienen ordenadas por prioridad (NO_CUMPLE y PARCIAL primero, por severidad). Use los filtros para ver solo lo abierto o un componente.
A21: • El nivel de cada regla (DEBE/DEBERÍA) es el predominante en el texto del estándar; algunas reglas mezclan ambos (p. ej. SEC-007, SEC-009) y el detalle está en la tabla de reglas de esta hoja.
A22: • El generador enmascara automáticamente secretos evidentes (JWT, claves privadas, password=...) en la evidencia.
A23: • Catálogo de reglas: versión 1.0.0 del estándar (Propuesta para revisión).
A25: Reglas del estándar
A26: ID | B26: Título | C26: Categoría | D26: Nivel | E26: Severidad base | F26: Aplica a | G26: Método | H26: Requisito del estándar | I26: Qué se verifica | J26: Cumple si | K26: No cumple si
A27: SEC-001 | B27: Proveedor de identidad | C27: Identidad y autenticación | D27: DEBE | E27: Alta | F27: frontend, mobile, gateway, microservicio, infraestructura | G27: Mixto | H27: Todos los clientes y servicios protegidos usan Keycloak como IdP centralizado, con configuración separada por ambiente para que tokens de desarrollo no sean aceptados en producción. | I27: • El issuer/authority/realm configurado apunta a Keycloak (o a un IdP compatible que cumple los mismos controles). • Existe configuración distinta por ambiente (perfiles, archivos environment, variables) y el perfil de producción no apunta al realm o URL de desarrollo. • No hay un segundo mecanismo de autenticación paralelo (usuarios locales, JWT propios firmados con clave simétrica compartida). | J27: El IdP es Keycloak o equivalente compatible y cada ambiente tiene su propio issuer/realm sin cruces. | K27: Producción usa el issuer de desarrollo, hay IdP o autenticación propia paralela, o no hay separación por ambiente.
A28: SEC-002 | B28: Protocolo OIDC sobre OAuth 2.0 | C28: Identidad y autenticación | D28: DEBE | E28: Alta | F28: frontend, mobile, gateway, microservicio | G28: Estático | H28: La autenticación usa OpenID Connect sobre OAuth 2.0; el frontend usa Authorization Code con PKCE; no existen formularios propios para almacenar o validar contraseñas. | I28: • El cliente público usa Authorization Code + PKCE (code_challenge_method S256). • No se usan flujos Implicit ni Resource Owner Password (grant_type=password). • No hay pantallas, endpoints o tablas propias que reciban, almacenen o validen contraseñas de usuarios finales. | J28: El flujo es Code+PKCE (frontend/mobile) y el backend no gestiona contraseñas de usuarios finales. | K28: Se usa Implicit/Password grant, falta PKCE en cliente público, o existe un login propio con contraseñas.
A29: SEC-003 | B29: Clientes de Keycloak por responsabilidad | C29: Identidad y autenticación | D29: DEBE | E29: Alta | F29: frontend, mobile, gateway, microservicio, infraestructura | G29: Estático | H29: Cliente público para frontend sin client_secret embebido; cliente de backend para autenticación de máquina; redirecciones y orígenes limitados a los dominios del ambiente; secretos de clientes confidenciales por variables de entorno o gestor de secretos. | I29: • El frontend/mobile no contiene client_secret en código, bundle, variables públicas ni repositorio. • Existen clientes separados para frontend y para servicios (service accounts). • redirectUris y webOrigins no usan comodín '*' ni dominios de otros ambientes. • El secreto de clientes confidenciales se lee de variables de entorno o gestor de secretos. | J29: Clientes separados, público sin secreto, redirecciones exactas por ambiente y secretos externalizados. | K29: Hay secreto en frontend, redirectUris con '*', o un único cliente compartido para frontend y backend.
A30: SEC-004 | B30: Validación de tokens JWT | C30: Identidad y autenticación | D30: DEBE | E30: Crítica | F30: gateway, microservicio | G30: Mixto | H30: Gateway y cada microservicio protegido validan el JWT: firma con claves públicas de Keycloak, iss, aud cuando aplique, exp y formato. No se confía en un identificador de usuario enviado por header, query o body si no coincide con la identidad autenticada. | I30: • Existe un resource server / middleware que valida la firma contra el JWKS de Keycloak. • Se valida issuer y expiración; se valida audience cuando el servicio lo requiere. • No hay decodificación sin verificación (decode sin verify, alg none, ignoreExpiration). • El userId usado en la lógica sale del token, no de header/param/body sin contrastar. • No hay rutas protegidas marcadas como permitAll por error. | J30: Firma, iss y exp se validan en el backend; audience se valida donde corresponde; la identidad proviene del token. | K30: No se valida la firma, el issuer o la expiración, o se confía en la identidad enviada por el cliente.
A31: SEC-005 | B31: Autorización en backend | C31: Autorización y roles | D31: DEBE | E31: Crítica | F31: gateway, microservicio | G31: Estático | H31: Los permisos se validan en el gateway y, de forma independiente, en el microservicio que ejecuta la operación. Ocultar un botón en el frontend no es autorización. | I31: • El gateway aplica reglas de autorización por ruta/rol. • Cada microservicio autoriza por sí mismo (anotaciones, reglas de seguridad o middleware) sin depender del gateway. • Ningún endpoint de negocio queda sin regla de autorización explícita. | J31: Todos los endpoints de negocio tienen autorización explícita validada en el propio servicio. | K31: Hay endpoints de negocio sin autorización, o el servicio confía únicamente en el gateway o en el frontend.
A32: SEC-006 | B32: Roles de negocio consistentes | C32: Autorización y roles | D32: DEBERÍA | E32: Media | F32: frontend, gateway, microservicio, infraestructura | G32: Estático | H32: El sistema usa roles de negocio claros (ADMIN, DIRECTOR, COORDINATOR, TEACHER, SECRETARY u otros definidos). Los nombres definitivos DEBEN ser consistentes entre Keycloak, gateway, microservicios y documentación. | I32: • El conjunto de roles usado en código coincide con los roles definidos en Keycloak (realm export). • Los nombres de rol son idénticos (mayúsculas, prefijos ROLE_) entre componentes. • La documentación del proyecto lista los mismos roles que la configuración real. | J32: Los roles coinciden entre Keycloak, código y documentación. | K32: Hay roles usados en código que no existen en Keycloak, nombres distintos entre componentes o documentación desactualizada.
A33: SEC-007 | B33: Menor privilegio por endpoint | C33: Autorización y roles | D33: DEBE | E33: Alta | F33: gateway, microservicio | G33: Estático | H33: Cada endpoint otorga solo el permiso necesario; no se usa un rol administrativo como solución general; lectura, creación, actualización y eliminación DEBERÍAN tener permisos diferenciados cuando el riesgo lo justifique. | I33: • No hay hasRole('ADMIN') (o equivalente) aplicado de forma generalizada para evitar errores de permisos. • Los endpoints de escritura/borrado exigen un permiso más restrictivo que los de lectura cuando el riesgo lo justifica. • Los roles asignados a cada endpoint se corresponden con quién necesita realmente la operación. | J33: Los permisos están acotados por endpoint y operación. | K33: Se usa ADMIN o 'authenticated' de forma indiscriminada, o endpoints sensibles quedan abiertos a roles que no los necesitan.
A34: SEC-008 | B34: Tenant derivado de la identidad autenticada | C34: Aislamiento multi-tenant | D34: DEBE | E34: Crítica | F34: frontend, mobile, gateway, microservicio | G34: Mixto | H34: Cada solicitud institucional se resuelve con el tenant asociado a la identidad autenticada o a un contexto confiable validado por el gateway. El frontend no puede cambiar de institución enviando solo otro tenantId. | I34: • El tenant efectivo se obtiene de un claim del token o de un header que el gateway sobrescribe y valida. • El gateway elimina o sobrescribe cualquier header de tenant enviado por el cliente. • Los servicios no aceptan tenantId de path/query/body como fuente de verdad sin contrastarlo con el tenant autenticado. • El frontend no puede elegir libremente el tenant (selección validada contra los tenants permitidos del usuario). | J34: El tenant sale de la identidad o de un contexto validado por el gateway y no es manipulable desde el cliente. | K34: Cambiar el tenantId en la petición cambia la institución consultada.
A35: SEC-009 | B35: Filtro obligatorio por tenant en datos | C35: Aislamiento multi-tenant | D35: DEBE | E35: Crítica | F35: microservicio | G35: Estático | H35: Las consultas y mutaciones de datos institucionales filtran por tenant. Claves únicas, índices y reglas de negocio DEBERÍAN considerar el tenant cuando los datos puedan repetirse entre instituciones. | I35: • Todas las consultas (JPA, SQL nativo, Mongo, R2DBC) sobre datos institucionales incluyen el predicado de tenant, o hay un filtro global confiable. • Las mutaciones (update/delete) también están acotadas por tenant. • Claves únicas e índices incluyen el tenant donde los valores pueden repetirse entre instituciones. | J35: No se encuentran accesos a datos institucionales sin acotar por tenant. | K35: Existen consultas o mutaciones de datos institucionales sin filtro de tenant.
A36: SEC-010 | B36: Prevención de fuga de datos entre tenants | C36: Aislamiento multi-tenant | D36: DEBE | E36: Crítica | F36: gateway, microservicio | G36: Mixto | H36: El sistema rechaza el acceso cuando usuario, recurso, estudiante, clase o institución no pertenecen al mismo contexto autorizado. Los errores no revelan información de otro tenant. | I36: • Antes de devolver o modificar un recurso se verifica que pertenece al tenant autorizado. • Los errores por recurso de otro tenant no distinguen 'existe pero no es tuyo' de 'no existe' ni incluyen datos ajenos. • Existen pruebas automáticas de acceso cruzado entre tenants. | J36: El acceso cruzado es rechazado y los errores no filtran información. | K36: Un usuario puede leer o modificar recursos de otro tenant, o los mensajes revelan datos de otro tenant.
A37: SEC-011 | B37: Comunicación autenticada entre servicios | C37: Seguridad entre microservicios | D37: DEBE | E37: Alta | F37: gateway, microservicio, integracion | G37: Estático | H37: Las llamadas entre servicios usan un contexto de autenticación válido. Con propagación de token, el receptor lo vuelve a validar; con credencial de servicio, esta se limita al servicio y permisos necesarios. | I37: • Los clientes HTTP internos (WebClient, RestTemplate, Feign, axios, fetch) envían un token o credencial de servicio. • El servicio receptor valida de nuevo el JWT; no confía en headers internos sin validar (X-Internal-*, X-User-*). • Las credenciales de servicio (client_credentials) tienen roles/scopes mínimos. | J37: Toda llamada interna lleva identidad válida y es verificada por el receptor. | K37: Hay llamadas internas sin autenticación, headers internos confiables sin validar o credenciales de servicio con privilegios excesivos.
