Workbook

Sheet Resumen
A1: Reporte de cumplimiento — Estándar general de seguridad, autenticación y autorización
A3: Proyecto | B3: vg-ms-certificate
A4: Versión del estándar | B4: 1.0.0
A5: Fecha del análisis | B5: 2026-10-23
A6: Generado por | B6: Jenkins · standards-ci (reglas automáticas)
A7: Alcance revisado | B7: Repositorio vg-ms-certificate: código, configuración y pruebas.
A9: Veredicto automático | B9: =IF(COUNTIFS(Resultados!$F$2:$F$2000,"DEBE",Resultados!$H$2:$H$2000,"NO_CUMPLE")>0,"NO APTO PARA APROBAR: hay incumplimientos de requisitos obligatorios (DEBE)",IF(COUNTIF(Resultados!$H$2:$H$2000,"SIN_EVALUAR")+COUNTIF(Resultados!$H$2:$H$2000,"REQUIERE_REVISION_MANUAL")+COUNTIFS(Resultados!$F$2:$F$2000,"DEBE",Resultados!$H$2:$H$2000,"PARCIAL")>0,"APROBACIÓN CONDICIONADA: hay verificaciones pendientes o cumplimientos parciales en requisitos DEBE","APTO (según evidencia revisada): sin incumplimientos obligatorios ni pendientes"))
A11: Indicadores clave
A12: Evaluaciones realizadas (componente × regla) | B12: =COUNTA(Resultados!$A$2:$A$2000)
A13: Cumplimiento global (ponderado) | B13: =IFERROR(SUM(Resultados!$J$2:$J$2000)/COUNT(Resultados!$J$2:$J$2000),"")
A14: Cumplimiento en requisitos obligatorios (DEBE) | B14: =IFERROR(SUMIFS(Resultados!$J$2:$J$2000,Resultados!$F$2:$F$2000,"DEBE")/COUNTIFS(Resultados!$F$2:$F$2000,"DEBE",Resultados!$J$2:$J$2000,">=0"),"")
A15: Cumplimiento en recomendaciones (DEBERÍA) | B15: =IFERROR(SUMIFS(Resultados!$J$2:$J$2000,Resultados!$F$2:$F$2000,"DEBERÍA")/COUNTIFS(Resultados!$F$2:$F$2000,"DEBERÍA",Resultados!$J$2:$J$2000,">=0"),"")
A16: Incumplimientos obligatorios abiertos (DEBE en NO_CUMPLE) | B16: =COUNTIFS(Resultados!$F$2:$F$2000,"DEBE",Resultados!$H$2:$H$2000,"NO_CUMPLE")
A17: El % pondera CUMPLE=1, NO_APLICA=1, PARCIAL=0.5 (ajustable en Leyenda) y NO_CUMPLE=0; REQUIERE_REVISION_MANUAL y SIN_EVALUAR no puntúan.
A19: Distribución por estado
A20: Estado | B20: Cantidad | C20: % del total
A21: CUMPLE | B21: =COUNTIF(Resultados!$H$2:$H$2000,A21) | C21: =IFERROR(B21/B$27,0)
A22: PARCIAL | B22: =COUNTIF(Resultados!$H$2:$H$2000,A22) | C22: =IFERROR(B22/B$27,0)
A23: NO_CUMPLE | B23: =COUNTIF(Resultados!$H$2:$H$2000,A23) | C23: =IFERROR(B23/B$27,0)
A24: NO_APLICA | B24: =COUNTIF(Resultados!$H$2:$H$2000,A24) | C24: =IFERROR(B24/B$27,0)
A25: REQUIERE_REVISION_MANUAL | B25: =COUNTIF(Resultados!$H$2:$H$2000,A25) | C25: =IFERROR(B25/B$27,0)
A26: SIN_EVALUAR | B26: =COUNTIF(Resultados!$H$2:$H$2000,A26) | C26: =IFERROR(B26/B$27,0)
A27: Total | B27: =SUM(B21:B26) | C27: =SUM(C21:C26)
A29: Cumplimiento por componente
A30: Componente | B30: Tipo | C30: CUMPLE | D30: PARCIAL | E30: NO_CUMPLE | F30: NO_APLICA | G30: REQUIERE_REVISION_MANUAL | H30: SIN_EVALUAR | I30: % cumplimiento
A31: vg-ms-certificate | B31: microservicio | C31: =COUNTIFS(Resultados!$A$2:$A$2000,$A31,Resultados!$H$2:$H$2000,C$30) | D31: =COUNTIFS(Resultados!$A$2:$A$2000,$A31,Resultados!$H$2:$H$2000,D$30) | E31: =COUNTIFS(Resultados!$A$2:$A$2000,$A31,Resultados!$H$2:$H$2000,E$30) | F31: =COUNTIFS(Resultados!$A$2:$A$2000,$A31,Resultados!$H$2:$H$2000,F$30) | G31: =COUNTIFS(Resultados!$A$2:$A$2000,$A31,Resultados!$H$2:$H$2000,G$30) | H31: =COUNTIFS(Resultados!$A$2:$A$2000,$A31,Resultados!$H$2:$H$2000,H$30) | I31: =IFERROR(SUMIFS(Resultados!$J$2:$J$2000,Resultados!$A$2:$A$2000,$A31)/COUNTIFS(Resultados!$A$2:$A$2000,$A31,Resultados!$J$2:$J$2000,">=0"),"")
A50: Cumplimiento por categoría del estándar
A51: Categoría | B51: Evaluaciones | C51: CUMPLE | D51: PARCIAL | E51: NO_CUMPLE | F51: NO_APLICA | G51: REQUIERE_REVISION_MANUAL | H51: SIN_EVALUAR | I51: % cumplimiento
A52: Identidad y autenticación | B52: =COUNTIFS(Resultados!$E$2:$E$2000,$A52) | C52: =COUNTIFS(Resultados!$E$2:$E$2000,$A52,Resultados!$H$2:$H$2000,C$51) | D52: =COUNTIFS(Resultados!$E$2:$E$2000,$A52,Resultados!$H$2:$H$2000,D$51) | E52: =COUNTIFS(Resultados!$E$2:$E$2000,$A52,Resultados!$H$2:$H$2000,E$51) | F52: =COUNTIFS(Resultados!$E$2:$E$2000,$A52,Resultados!$H$2:$H$2000,F$51) | G52: =COUNTIFS(Resultados!$E$2:$E$2000,$A52,Resultados!$H$2:$H$2000,G$51) | H52: =COUNTIFS(Resultados!$E$2:$E$2000,$A52,Resultados!$H$2:$H$2000,H$51) | I52: =IFERROR(SUMIFS(Resultados!$J$2:$J$2000,Resultados!$E$2:$E$2000,$A52)/COUNTIFS(Resultados!$E$2:$E$2000,$A52,Resultados!$J$2:$J$2000,">=0"),"")
A53: Autorización y roles | B53: =COUNTIFS(Resultados!$E$2:$E$2000,$A53) | C53: =COUNTIFS(Resultados!$E$2:$E$2000,$A53,Resultados!$H$2:$H$2000,C$51) | D53: =COUNTIFS(Resultados!$E$2:$E$2000,$A53,Resultados!$H$2:$H$2000,D$51) | E53: =COUNTIFS(Resultados!$E$2:$E$2000,$A53,Resultados!$H$2:$H$2000,E$51) | F53: =COUNTIFS(Resultados!$E$2:$E$2000,$A53,Resultados!$H$2:$H$2000,F$51) | G53: =COUNTIFS(Resultados!$E$2:$E$2000,$A53,Resultados!$H$2:$H$2000,G$51) | H53: =COUNTIFS(Resultados!$E$2:$E$2000,$A53,Resultados!$H$2:$H$2000,H$51) | I53: =IFERROR(SUMIFS(Resultados!$J$2:$J$2000,Resultados!$E$2:$E$2000,$A53)/COUNTIFS(Resultados!$E$2:$E$2000,$A53,Resultados!$J$2:$J$2000,">=0"),"")
A54: Aislamiento multi-tenant | B54: =COUNTIFS(Resultados!$E$2:$E$2000,$A54) | C54: =COUNTIFS(Resultados!$E$2:$E$2000,$A54,Resultados!$H$2:$H$2000,C$51) | D54: =COUNTIFS(Resultados!$E$2:$E$2000,$A54,Resultados!$H$2:$H$2000,D$51) | E54: =COUNTIFS(Resultados!$E$2:$E$2000,$A54,Resultados!$H$2:$H$2000,E$51) | F54: =COUNTIFS(Resultados!$E$2:$E$2000,$A54,Resultados!$H$2:$H$2000,F$51) | G54: =COUNTIFS(Resultados!$E$2:$E$2000,$A54,Resultados!$H$2:$H$2000,G$51) | H54: =COUNTIFS(Resultados!$E$2:$E$2000,$A54,Resultados!$H$2:$H$2000,H$51) | I54: =IFERROR(SUMIFS(Resultados!$J$2:$J$2000,Resultados!$E$2:$E$2000,$A54)/COUNTIFS(Resultados!$E$2:$E$2000,$A54,Resultados!$J$2:$J$2000,">=0"),"")
A55: Seguridad entre microservicios | B55: =COUNTIFS(Resultados!$E$2:$E$2000,$A55) | C55: =COUNTIFS(Resultados!$E$2:$E$2000,$A55,Resultados!$H$2:$H$2000,C$51) | D55: =COUNTIFS(Resultados!$E$2:$E$2000,$A55,Resultados!$H$2:$H$2000,D$51) | E55: =COUNTIFS(Resultados!$E$2:$E$2000,$A55,Resultados!$H$2:$H$2000,E$51) | F55: =COUNTIFS(Resultados!$E$2:$E$2000,$A55,Resultados!$H$2:$H$2000,F$51) | G55: =COUNTIFS(Resultados!$E$2:$E$2000,$A55,Resultados!$H$2:$H$2000,G$51) | H55: =COUNTIFS(Resultados!$E$2:$E$2000,$A55,Resultados!$H$2:$H$2000,H$51) | I55: =IFERROR(SUMIFS(Resultados!$J$2:$J$2000,Resultados!$E$2:$E$2000,$A55)/COUNTIFS(Resultados!$E$2:$E$2000,$A55,Resultados!$J$2:$J$2000,">=0"),"")
A56: Datos, secretos y configuración | B56: =COUNTIFS(Resultados!$E$2:$E$2000,$A56) | C56: =COUNTIFS(Resultados!$E$2:$E$2000,$A56,Resultados!$H$2:$H$2000,C$51) | D56: =COUNTIFS(Resultados!$E$2:$E$2000,$A56,Resultados!$H$2:$H$2000,D$51) | E56: =COUNTIFS(Resultados!$E$2:$E$2000,$A56,Resultados!$H$2:$H$2000,E$51) | F56: =COUNTIFS(Resultados!$E$2:$E$2000,$A56,Resultados!$H$2:$H$2000,F$51) | G56: =COUNTIFS(Resultados!$E$2:$E$2000,$A56,Resultados!$H$2:$H$2000,G$51) | H56: =COUNTIFS(Resultados!$E$2:$E$2000,$A56,Resultados!$H$2:$H$2000,H$51) | I56: =IFERROR(SUMIFS(Resultados!$J$2:$J$2000,Resultados!$E$2:$E$2000,$A56)/COUNTIFS(Resultados!$E$2:$E$2000,$A56,Resultados!$J$2:$J$2000,">=0"),"")
A57: Errores, logs y auditoría | B57: =COUNTIFS(Resultados!$E$2:$E$2000,$A57) | C57: =COUNTIFS(Resultados!$E$2:$E$2000,$A57,Resultados!$H$2:$H$2000,C$51) | D57: =COUNTIFS(Resultados!$E$2:$E$2000,$A57,Resultados!$H$2:$H$2000,D$51) | E57: =COUNTIFS(Resultados!$E$2:$E$2000,$A57,Resultados!$H$2:$H$2000,E$51) | F57: =COUNTIFS(Resultados!$E$2:$E$2000,$A57,Resultados!$H$2:$H$2000,F$51) | G57: =COUNTIFS(Resultados!$E$2:$E$2000,$A57,Resultados!$H$2:$H$2000,G$51) | H57: =COUNTIFS(Resultados!$E$2:$E$2000,$A57,Resultados!$H$2:$H$2000,H$51) | I57: =IFERROR(SUMIFS(Resultados!$J$2:$J$2000,Resultados!$E$2:$E$2000,$A57)/COUNTIFS(Resultados!$E$2:$E$2000,$A57,Resultados!$J$2:$J$2000,">=0"),"")
A58: Integridad transversal | B58: =COUNTIFS(Resultados!$E$2:$E$2000,$A58) | C58: =COUNTIFS(Resultados!$E$2:$E$2000,$A58,Resultados!$H$2:$H$2000,C$51) | D58: =COUNTIFS(Resultados!$E$2:$E$2000,$A58,Resultados!$H$2:$H$2000,D$51) | E58: =COUNTIFS(Resultados!$E$2:$E$2000,$A58,Resultados!$H$2:$H$2000,E$51) | F58: =COUNTIFS(Resultados!$E$2:$E$2000,$A58,Resultados!$H$2:$H$2000,F$51) | G58: =COUNTIFS(Resultados!$E$2:$E$2000,$A58,Resultados!$H$2:$H$2000,G$51) | H58: =COUNTIFS(Resultados!$E$2:$E$2000,$A58,Resultados!$H$2:$H$2000,H$51) | I58: =IFERROR(SUMIFS(Resultados!$J$2:$J$2000,Resultados!$E$2:$E$2000,$A58)/COUNTIFS(Resultados!$E$2:$E$2000,$A58,Resultados!$J$2:$J$2000,">=0"),"")
A60: Hallazgos abiertos por severidad
A61: Severidad | B61: NO_CUMPLE | C61: PARCIAL | D61: Total
A62: Crítica | B62: =COUNTIFS(Resultados!$I$2:$I$2000,$A62,Resultados!$H$2:$H$2000,B$61) | C62: =COUNTIFS(Resultados!$I$2:$I$2000,$A62,Resultados!$H$2:$H$2000,C$61) | D62: =B62+C62
A63: Alta | B63: =COUNTIFS(Resultados!$I$2:$I$2000,$A63,Resultados!$H$2:$H$2000,B$61) | C63: =COUNTIFS(Resultados!$I$2:$I$2000,$A63,Resultados!$H$2:$H$2000,C$61) | D63: =B63+C63
A64: Media | B64: =COUNTIFS(Resultados!$I$2:$I$2000,$A64,Resultados!$H$2:$H$2000,B$61) | C64: =COUNTIFS(Resultados!$I$2:$I$2000,$A64,Resultados!$H$2:$H$2000,C$61) | D64: =B64+C64
...

Sheet Matriz
A1: Matriz de cumplimiento: regla × componente
A2: Se alimenta con fórmulas desde la hoja Resultados. '—' = la regla no aplica o no tiene fila.
C3: Tipo → | D3: microservicio
A4: Regla | B4: Título | C4: Nivel | D4: vg-ms-certificate
A5: SEC-001 | B5: Proveedor de identidad | C5: DEBE | D5: =IFERROR(INDEX(Resultados!$H$2:$H$2000,MATCH(D$4&"|"&$A5,Resultados!$P$2:$P$2000,0)),"—")
A6: SEC-002 | B6: Protocolo OIDC sobre OAuth 2.0 | C6: DEBE | D6: =IFERROR(INDEX(Resultados!$H$2:$H$2000,MATCH(D$4&"|"&$A6,Resultados!$P$2:$P$2000,0)),"—")
A7: SEC-003 | B7: Clientes de Keycloak por responsabilidad | C7: DEBE | D7: =IFERROR(INDEX(Resultados!$H$2:$H$2000,MATCH(D$4&"|"&$A7,Resultados!$P$2:$P$2000,0)),"—")
A8: SEC-004 | B8: Validación de tokens JWT | C8: DEBE | D8: =IFERROR(INDEX(Resultados!$H$2:$H$2000,MATCH(D$4&"|"&$A8,Resultados!$P$2:$P$2000,0)),"—")
A9: SEC-005 | B9: Autorización en backend | C9: DEBE | D9: =IFERROR(INDEX(Resultados!$H$2:$H$2000,MATCH(D$4&"|"&$A9,Resultados!$P$2:$P$2000,0)),"—")
A10: SEC-006 | B10: Roles de negocio consistentes | C10: DEBERÍA | D10: =IFERROR(INDEX(Resultados!$H$2:$H$2000,MATCH(D$4&"|"&$A10,Resultados!$P$2:$P$2000,0)),"—")
A11: SEC-007 | B11: Menor privilegio por endpoint | C11: DEBE | D11: =IFERROR(INDEX(Resultados!$H$2:$H$2000,MATCH(D$4&"|"&$A11,Resultados!$P$2:$P$2000,0)),"—")
A12: SEC-008 | B12: Tenant derivado de la identidad autenticada | C12: DEBE | D12: =IFERROR(INDEX(Resultados!$H$2:$H$2000,MATCH(D$4&"|"&$A12,Resultados!$P$2:$P$2000,0)),"—")
A13: SEC-009 | B13: Filtro obligatorio por tenant en datos | C13: DEBE | D13: =IFERROR(INDEX(Resultados!$H$2:$H$2000,MATCH(D$4&"|"&$A13,Resultados!$P$2:$P$2000,0)),"—")
A14: SEC-010 | B14: Prevención de fuga de datos entre tenants | C14: DEBE | D14: =IFERROR(INDEX(Resultados!$H$2:$H$2000,MATCH(D$4&"|"&$A14,Resultados!$P$2:$P$2000,0)),"—")
A15: SEC-011 | B15: Comunicación autenticada entre servicios | C15: DEBE | D15: =IFERROR(INDEX(Resultados!$H$2:$H$2000,MATCH(D$4&"|"&$A15,Resultados!$P$2:$P$2000,0)),"—")
A16: SEC-012 | B16: Gateway como único punto de entrada público | C16: DEBERÍA | D16: =IFERROR(INDEX(Resultados!$H$2:$H$2000,MATCH(D$4&"|"&$A16,Resultados!$P$2:$P$2000,0)),"—")
... A26: SEC-022 | B26: Idempotencia y control de concurrencia | C26: DEBERÍA | D26: =IFERROR(INDEX(Resultados!$H$2:$H$2000,MATCH(D$4&"|"&$A26,Resultados!$P$2:$P$2000,0)),"—")

Sheet Resultados
A1: Componente | B1: Tipo | C1: Regla | D1: Título de la regla | E1: Categoría | F1: Nivel | G1: Método | H1: Estado | I1: Severidad | J1: Puntaje | K1: Evidencia (archivo:línea — detalle) | L1: Observación | M1: Recomendación | N1: Responsable | O1: Fecha compromiso | P1: Clave auxiliar
A2: vg-ms-certificate | B2: microservicio | C2: SEC-001 | D2: Proveedor de identidad | E2: Identidad y autenticación | F2: DEBE | G2: Mixto | H2: CUMPLE | J2: =IFERROR(IF(ISNUMBER(VLOOKUP(H2,Leyenda!$A$5:$C$10,3,FALSE)),VLOOKUP(H2,Leyenda!$A$5:$C$10,3,FALSE),""),"") | K2: src/main/resources/application.yml:48 — El issuer de Keycloak llega por variable de entorno. src/main/resources/application.yml:49 — Las claves públicas se leen del JWKS. | L2: Keycloak es el único proveedor; cada ambiente define su realm por variable de entorno. | P2: =A2&"|"&C2
A3: vg-ms-certificate | B3: microservicio | C3: SEC-002 | D3: Protocolo OIDC sobre OAuth 2.0 | E3: Identidad y autenticación | F3: DEBE | G3: Estático | H3: CUMPLE | J3: =IFERROR(IF(ISNUMBER(VLOOKUP(H3,Leyenda!$A$5:$C$10,3,FALSE)),VLOOKUP(H3,Leyenda!$A$5:$C$10,3,FALSE),""),"") | K3: src/main/java/pe/edu/vallegrande/fideinexus/certificate/infrastructure/config/SecurityConfig.java:48 — Resource server OAuth 2.0 con JWT de Keycloak. | L3: Los tokens son JWT emitidos por Keycloak con OIDC. | P3: =A3&"|"&C3
A4: vg-ms-certificate | B4: microservicio | C4: SEC-003 | D4: Clientes de Keycloak por responsabilidad | E4: Identidad y autenticación | F4: DEBE | G4: Manual | H4: PARCIAL | I4: Alta | J4: =IFERROR(IF(ISNUMBER(VLOOKUP(H4,Leyenda!$A$5:$C$10,3,FALSE)),VLOOKUP(H4,Leyenda!$A$5:$C$10,3,FALSE),""),"") | K4: docs/keycloak/prs-realm-export.json:858 — prs-frontend y fideiNexus aceptan cualquier redirect URI. docs/keycloak/prs-realm-export.json:920 — Cliente propio para Postman, público y separado del frontend. | L4: Revisión manual del 2026-10-22: Los clientes están separados por aplicación y prs-postman cumple: público, Authorization Code con PKCE S256, sin Direct Access Grants y con redirect exacto. prs-frontend y fideiNexus mantienen Direct Access Grants porque la web inicia sesión con contraseña, y aceptan cualquier redirect URI. | M4: Restringir Valid redirect URIs y Web origins de prs-frontend y fideiNexus al dominio real de la web, y migrar el login de la web a Authorization Code con PKCE para apagar Direct Access Grants. | P4: =A4&"|"&C4
A5: vg-ms-certificate | B5: microservicio | C5: SEC-004 | D5: Validación de tokens JWT | E5: Identidad y autenticación | F5: DEBE | G5: Mixto | H5: CUMPLE | J5: =IFERROR(IF(ISNUMBER(VLOOKUP(H5,Leyenda!$A$5:$C$10,3,FALSE)),VLOOKUP(H5,Leyenda!$A$5:$C$10,3,FALSE),""),"") | K5: src/main/java/pe/edu/vallegrande/fideinexus/certificate/infrastructure/config/SecurityConfig.java:48 — Valida firma con el JWKS. src/main/java/pe/edu/vallegrande/fideinexus/certificate/infrastructure/config/SecurityConfig.java:13 — Valida issuer, vigencia y datos del token. | L5: Firma, issuer y vencimiento se validan en cada petición. | P5: =A5&"|"&C5
A6: vg-ms-certificate | B6: microservicio | C6: SEC-005 | D6: Autorización en backend | E6: Autorización y roles | F6: DEBE | G6: Estático | H6: CUMPLE | J6: =IFERROR(IF(ISNUMBER(VLOOKUP(H6,Leyenda!$A$5:$C$10,3,FALSE)),VLOOKUP(H6,Leyenda!$A$5:$C$10,3,FALSE),""),"") | K6: src/main/java/pe/edu/vallegrande/fideinexus/certificate/infrastructure/config/SecurityConfig.java:44 — Todo lo no público exige autenticación. src/main/java/pe/edu/vallegrande/fideinexus/certificate/infrastructure/adapter/in/rest/controller/CertificateRest.java:78 — Los roles se comprueban en el backend. | L6: La autorización se decide en el servicio, no en el front. | P6: =A6&"|"&C6
A7: vg-ms-certificate | B7: microservicio | C7: SEC-006 | D7: Roles de negocio consistentes | E7: Autorización y roles | F7: DEBERÍA | G7: Estático | H7: CUMPLE | J7: =IFERROR(IF(ISNUMBER(VLOOKUP(H7,Leyenda!$A$5:$C$10,3,FALSE)),VLOOKUP(H7,Leyenda!$A$5:$C$10,3,FALSE),""),"") | K7: src/main/java/pe/edu/vallegrande/fideinexus/certificate/infrastructure/security/KeycloakRoleConverter.java:15 — Roles: FELIGRES, PARROCO, SECRETARIO, SUPERADMIN. | L7: Los roles coinciden con el catálogo del PRS. | P7: =A7&"|"&C7
A8: vg-ms-certificate | B8: microservicio | C8: SEC-007 | D8: Menor privilegio por endpoint | E8: Autorización y roles | F8: DEBE | G8: Estático | H8: CUMPLE | J8: =IFERROR(IF(ISNUMBER(VLOOKUP(H8,Leyenda!$A$5:$C$10,3,FALSE)),VLOOKUP(H8,Leyenda!$A$5:$C$10,3,FALSE),""),"") | K8: src/main/java/pe/edu/vallegrande/fideinexus/certificate/infrastructure/config/SecurityConfig.java:43 — Solo las rutas públicas quedan abiertas. src/main/java/pe/edu/vallegrande/fideinexus/certificate/infrastructure/config/SecurityConfig.java:44 — El resto exige token. | L8: Cada endpoint pide el mínimo necesario. | P8: =A8&"|"&C8
A9: vg-ms-certificate | B9: microservicio | C9: SEC-008 | D9: Tenant derivado de la identidad autenticada | E9: Aislamiento multi-tenant | F9: DEBE | G9: Estático | H9: CUMPLE | J9: =IFERROR(IF(ISNUMBER(VLOOKUP(H9,Leyenda!$A$5:$C$10,3,FALSE)),VLOOKUP(H9,Leyenda!$A$5:$C$10,3,FALSE),""),"") | K9: src/main/java/pe/edu/vallegrande/fideinexus/certificate/infrastructure/adapter/out/client/security/JwtSecurityContextClientAdapter.java:44 — El tenant sale del token. | L9: El tenant se toma del JWT; el cliente no lo elige. | P9: =A9&"|"&C9
A10: vg-ms-certificate | B10: microservicio | C10: SEC-009 | D10: Filtro obligatorio por tenant en datos | E10: Aislamiento multi-tenant | F10: DEBE | G10: Estático | H10: CUMPLE | J10: =IFERROR(IF(ISNUMBER(VLOOKUP(H10,Leyenda!$A$5:$C$10,3,FALSE)),VLOOKUP(H10,Leyenda!$A$5:$C$10,3,FALSE),""),"") | K10: src/main/java/pe/edu/vallegrande/fideinexus/certificate/domain/port/out/CertificateRepositoryPort.java:13 — Las consultas filtran por tenant. | L10: Toda consulta incluye el tenant. | P10: =A10&"|"&C10
A11: vg-ms-certificate | B11: microservicio | C11: SEC-010 | D11: Prevención de fuga de datos entre tenants | E11: Aislamiento multi-tenant | F11: DEBE | G11: Estático | H11: CUMPLE | J11: =IFERROR(IF(ISNUMBER(VLOOKUP(H11,Leyenda!$A$5:$C$10,3,FALSE)),VLOOKUP(H11,Leyenda!$A$5:$C$10,3,FALSE),""),"") | K11: src/main/java/pe/edu/vallegrande/fideinexus/certificate/domain/exception/TenantAccessException.java:4 — Se comprueba la parroquia antes de devolver datos. src/test/java/pe/edu/vallegrande/fideinexus/certificate/application/usecase/CertificateServiceTest.java:173 — Prueba de acceso desde otra parroquia. | L11: Una parroquia no ve ni cambia datos de otra. | P11: =A11&"|"&C11
A12: vg-ms-certificate | B12: microservicio | C12: SEC-011 | D12: Comunicación autenticada entre servicios | E12: Seguridad entre microservicios | F12: DEBE | G12: Estático | H12: NO_APLICA | J12: =IFERROR(IF(ISNUMBER(VLOOKUP(H12,Leyenda!$A$5:$C$10,3,FALSE)),VLOOKUP(H12,Leyenda!$A$5:$C$10,3,FALSE),""),"") | L12: El servicio no llama a otros microservicios. | P12: =A12&"|"&C12
A13: vg-ms-certificate | B13: microservicio | C13: SEC-012 | D13: Gateway como único punto de entrada público | E13: Seguridad entre microservicios | F13: DEBERÍA | G13: Manual | H13: CUMPLE | J13: =IFERROR(IF(ISNUMBER(VLOOKUP(H13,Leyenda!$A$5:$C$10,3,FALSE)),VLOOKUP(H13,Leyenda!$A$5:$C$10,3,FALSE),""),"") | K13: PRS-GATEWAY/docker-compose.dokploy.yml:279 — El servicio no publica puertos al host; solo el gateway. PRS-GATEWAY/vg-ms-gateway/src/main/resources/application-prod.yml:27 — El gateway enruta solo la API; swagger y actuator no tienen ruta pública. | L13: Revisión manual del 2026-10-22: La evidencia está en PRS-GATEWAY, fuera del repositorio del servicio. | P13: =A13&"|"&C13
A14: vg-ms-certificate | B14: microservicio | C14: SEC-013 | D14: CORS restringido por ambiente | E14: Seguridad entre microservicios | F14: DEBE | G14: Estático | H14: CUMPLE | J14: =IFERROR(IF(ISNUMBER(VLOOKUP(H14,Leyenda!$A$5:$C$10,3,FALSE)),VLOOKUP(H14,Leyenda!$A$5:$C$10,3,FALSE),""),"") | K14: src/main/resources/application.yml:62 — Orígenes permitidos por variable de entorno. | L14: Cada ambiente define sus orígenes; no hay comodín. | P14: =A14&"|"&C14
A15: vg-ms-certificate | B15: microservicio | C15: SEC-014 | D15: Gestión de secretos | E15: Datos, secretos y configuración | F15: DEBE | G15: Estático | H15: CUMPLE | J15: =IFERROR(IF(ISNUMBER(VLOOKUP(H15,Leyenda!$A$5:$C$10,3,FALSE)),VLOOKUP(H15,Leyenda!$A$5:$C$10,3,FALSE),""),"") | K15: .gitignore:6 — .env está ignorado por git. | L15: Los secretos viven en variables de entorno; .env no se versiona. | P15: =A15&"|"&C15
A16: vg-ms-certificate | B16: microservicio | C16: SEC-015 | D16: Transporte seguro (HTTPS/TLS) | E16: Datos, secretos y configuración | F16: DEBE | G16: Mixto | H16: CUMPLE | J16: =IFERROR(IF(ISNUMBER(VLOOKUP(H16,Leyenda!$A$5:$C$10,3,FALSE)),VLOOKUP(H16,Leyenda!$A$5:$C$10,3,FALSE),""),"") | K16: src/main/resources/application-prod.yml:7 — La conexión a la base exige TLS. src/main/resources/application.yml:22 — La conexión a la base exige TLS. src/main/resources/application.yml:22 — La base exige TLS. | L16: Revisión manual del 2026-10-22: Las llamadas entre contenedores van por la red interna de Docker, no por Internet. | P16: =A16&"|"&C16
A17: vg-ms-certificate | B17: microservicio | C17: SEC-016 | D17: Validación de entrada | E17: Datos, secretos y configuración | F17: DEBE | G17: Estático | H17: CUMPLE | J17: =IFERROR(IF(ISNUMBER(VLOOKUP(H17,Leyenda!$A$5:$C$10,3,FALSE)),VLOOKUP(H17,Leyenda!$A$5:$C$10,3,FALSE),""),"") | K17: src/main/java/pe/edu/vallegrande/fideinexus/certificate/infrastructure/adapter/in/rest/controller/CertificateRest.java:143 — Se valida el cuerpo al entrar. src/main/java/pe/edu/vallegrande/fideinexus/certificate/infrastructure/adapter/in/rest/dto/request/CertificateGenerateRequest.java:9 — Reglas de validación en el request. | L17: La entrada se valida en el backend aunque el front ya valide. | P17: =A17&"|"&C17
A18: vg-ms-certificate | B18: microservicio | C18: SEC-017 | D18: Respuestas de error diferenciadas y seguras | E18: Errores, logs y auditoría | F18: DEBE | G18: Mixto | H18: CUMPLE | J18: =IFERROR(IF(ISNUMBER(VLOOKUP(H18,Leyenda!$A$5:$C$10,3,FALSE)),VLOOKUP(H18,Leyenda!$A$5:$C$10,3,FALSE),""),"") | K18: src/main/java/pe/edu/vallegrande/fideinexus/certificate/infrastructure/exception/GlobalExceptionHandler.java:31 — Respuestas diferenciadas: BAD_REQUEST, CONFLICT, FORBIDDEN, INTERNAL_SERVER_ERROR, METHOD_NOT_ALLOWED, NOT_ACCEPTABLE, NOT_FOUND, UNPROCESSABLE_ENTITY, UNSUPPORTED_MEDIA_TYPE. | L18: Cada error tiene su código y un mensaje sin detalles internos. | P18: =A18&"|"&C18
A19: vg-ms-certificate | B19: microservicio | C19: SEC-018 | D19: Logs seguros | E19: Errores, logs y auditoría | F19: DEBE | G19: Estático | H19: CUMPLE | J19: =IFERROR(IF(ISNUMBER(VLOOKUP(H19,Leyenda!$A$5:$C$10,3,FALSE)),VLOOKUP(H19,Leyenda!$A$5:$C$10,3,FALSE),""),"") | K19: src/main/java/pe/edu/vallegrande/fideinexus/certificate/application/usecase/CertificateService.java:147 — Logs revisados. | L19: Los logs no imprimen tokens ni datos sensibles. | P19: =A19&"|"&C19
A20: vg-ms-certificate | B20: microservicio | C20: SEC-019 | D20: Auditoría de operaciones sensibles | E20: Errores, logs y auditoría | F20: DEBE | G20: Estático | H20: CUMPLE | J20: =IFERROR(IF(ISNUMBER(VLOOKUP(H20,Leyenda!$A$5:$C$10,3,FALSE)),VLOOKUP(H20,Leyenda!$A$5:$C$10,3,FALSE),""),"") | K20: src/main/java/pe/edu/vallegrande/fideinexus/certificate/domain/model/AuditLog.java:12 — Las operaciones de escritura dejan registro de auditoría. | L20: Crear, editar y eliminar quedan auditados. | P20: =A20&"|"&C20
A21: vg-ms-certificate | B21: microservicio | C21: SEC-020 | D21: Control de pertenencia sobre recursos | E21: Integridad transversal | F21: DEBE | G21: Estático | H21: CUMPLE | J21: =IFERROR(IF(ISNUMBER(VLOOKUP(H21,Leyenda!$A$5:$C$10,3,FALSE)),VLOOKUP(H21,Leyenda!$A$5:$C$10,3,FALSE),""),"") | K21: src/main/java/pe/edu/vallegrande/fideinexus/certificate/domain/exception/TenantAccessException.java:4 — Se comprueba que el recurso sea de la parroquia del usuario. | L21: Antes de leer o cambiar un recurso se valida su pertenencia. | P21: =A21&"|"&C21
A22: vg-ms-certificate | B22: microservicio | C22: SEC-021 | D22: Integridad de contexto | E22: Integridad transversal | F22: DEBE | G22: Estático | H22: CUMPLE | J22: =IFERROR(IF(ISNUMBER(VLOOKUP(H22,Leyenda!$A$5:$C$10,3,FALSE)),VLOOKUP(H22,Leyenda!$A$5:$C$10,3,FALSE),""),"") | K22: src/main/java/pe/edu/vallegrande/fideinexus/certificate/infrastructure/adapter/out/client/security/JwtSecurityContextClientAdapter.java:23 — El contexto sale del token, no del body. | L22: El cliente no puede cambiar tenant ni autor. | P22: =A22&"|"&C22
A23: vg-ms-certificate | B23: microservicio | C23: SEC-022 | D23: Idempotencia y control de concurrencia | E23: Integridad transversal | F23: DEBERÍA | G23: Estático | H23: CUMPLE | J23: =IFERROR(IF(ISNUMBER(VLOOKUP(H23,Leyenda!$A$5:$C$10,3,FALSE)),VLOOKUP(H23,Leyenda!$A$5:$C$10,3,FALSE),""),"") | K23: src/main/java/pe/edu/vallegrande/fideinexus/certificate/infrastructure/adapter/out/persistence/r2dbc/entity/CertificateEntity.java:44 — Se detectan duplicados o colisiones y se responde 409. | L23: Un reintento no duplica registros. | P23: =A23&"|"&C23

Sheet Hallazgos
A1: Hallazgos abiertos (NO_CUMPLE y PARCIAL), ordenados por severidad
A2: Instantánea generada con el reporte. La fuente viva de datos es la hoja Resultados. Complete responsable, fecha y estado de remediación.
A4: ID | B4: Componente | C4: Regla | D4: Título | E4: Nivel | F4: Severidad | G4: Estado | H4: Observación | I4: Evidencia | J4: Recomendación | K4: Responsable | L4: Fecha compromiso | M4: Estado de remediación
A5: H-001 | B5: vg-ms-certificate | C5: SEC-003 | D5: Clientes de Keycloak por responsabilidad | E5: DEBE | F5: Alta | G5: PARCIAL | H5: Revisión manual del 2026-10-22: Los clientes están separados por aplicación y prs-postman cumple: público, Authorization Code con PKCE S256, sin Direct Access Grants y con redirect exacto. prs-frontend y fideiNexus mantienen Direct Access Grants porque la web inicia sesión con contraseña, y aceptan cualquier redirect URI. | I5: docs/keycloak/prs-realm-export.json:858 — prs-frontend y fideiNexus aceptan cualquier redirect URI. docs/keycloak/prs-realm-export.json:920 — Cliente propio para Postman, público y separado del frontend. | J5: Restringir Valid redirect URIs y Web origins de prs-frontend y fideiNexus al dominio real de la web, y migrar el login de la web a Authorization Code con PKCE para apagar Direct Access Grants. | M5: Abierto

Sheet Pruebas
A1: ID | B1: Prueba mínima (sección 11) | C1: Resultado esperado | D1: Reglas relacionadas | E1: Estado | F1: Método | G1: Componentes probados | H1: Evidencia | I1: Observación
A2: T01 | B2: Solicitud sin token | C2: Responde 401. | D2: SEC-004, SEC-017 | E2: REQUIERE_REVISION_MANUAL | F2: Manual | I2: No hay una prueba automatizada que lo cubra.
A3: T02 | B3: Token vencido o con issuer incorrecto | C3: Responde 401. | D3: SEC-004 | E3: REQUIERE_REVISION_MANUAL | F3: Manual | I3: No hay una prueba automatizada que lo cubra.
A4: T03 | B4: Usuario autenticado sin rol | C4: Responde 403. | D4: SEC-005, SEC-007 | E4: REQUIERE_REVISION_MANUAL | F4: Manual | I4: No hay una prueba automatizada que lo cubra.
A5: T04 | B5: Usuario de otro tenant | C5: No puede leer ni modificar el recurso. | D5: SEC-008, SEC-009, SEC-010 | E5: CUMPLE | F5: Estático | H5: src/test/java/pe/edu/vallegrande/fideinexus/certificate/application/usecase/CertificateServiceTest.java:173 — Prueba automatizada que lo cubre. | I5: Prueba dinámica con dos tenants. Estático: pruebas de aislamiento existentes y filtros de tenant en acceso a datos.
A6: T05 | B6: Docente intentando usar otra clase | C6: La operación es rechazada. | D6: SEC-020 | E6: NO_APLICA | F6: Estático | I6: La prueba es para un docente que usa otra clase; en una parroquia no hay clases ni docentes.
A7: T06 | B7: Token o secreto en logs o respuestas | C7: No aparece. | D7: SEC-014, SEC-017, SEC-018 | E7: REQUIERE_REVISION_MANUAL | F7: Manual | I7: No hay una prueba automatizada que lo cubra.
A8: T07 | B8: Reintento de operación masiva | C8: No duplica datos. | D8: SEC-022 | E8: REQUIERE_REVISION_MANUAL | F8: Manual | I8: No hay una prueba automatizada que lo cubra.
A9: T08 | B9: CORS con origen no autorizado | C9: Se rechaza. | D9: SEC-013 | E9: REQUIERE_REVISION_MANUAL | F9: Manual | I9: No hay una prueba automatizada que lo cubra.
A10: T09 | B10: Datos inválidos con frontend manipulado | C10: El servicio los rechaza igualmente. | D10: SEC-016 | E10: REQUIERE_REVISION_MANUAL | F10: Manual | I10: No hay una prueba automatizada que lo cubra.
A12: Si no hay observación, la columna muestra cómo verificar la prueba. SIN_EVALUAR = prueba no ejecutada ni confirmada por pruebas automatizadas existentes.

Sheet Checklist
A1: Checklist para revisión (sección 12 del estándar)
A2: Estado calculado con fórmulas a partir de las reglas y pruebas vinculadas. Peor resultado manda: cualquier NO_CUMPLE → NO CUMPLE.
A4: # | B4: Ítem del checklist | C4: Reglas / pruebas vinculadas | D4: Estado | E4: Comentario del revisor
A5: 1 | B5: Keycloak está configurado por ambiente. | C5: SEC-001 | D5: =IF(COUNTIFS(Resultados!$C$2:$C$2000,"SEC-001",Resultados!$H$2:$H$2000,"NO_CUMPLE")>0,"NO CUMPLE",IF(COUNTIFS(Resultados!$C$2:$C$2000,"SEC-001",Resultados!$H$2:$H$2000,"PARCIAL")+COUNTIFS(Resultados!$C$2:$C$2000,"SEC-001",Resultados!$H$2:$H$2000,"REQUIERE_REVISION_MANUAL")+COUNTIFS(Resultados!$C$2:$C$2000,"SEC-001",Resultados!$H$2:$H$2000,"SIN_EVALUAR")>0,"PARCIAL / PENDIENTE",IF(COUNTIFS(Resultados!$C$2:$C$2000,"SEC-001",Resultados!$H$2:$H$2000,"CUMPLE")>0,"CUMPLE",IF(COUNTIFS(Resultados!$C$2:$C$2000,"SEC-001",Resultados!$H$2:$H$2000,"NO_APLICA")>0,"NO APLICA","SIN DATOS"))))
A6: 2 | B6: Los clientes tienen responsabilidades separadas. | C6: SEC-003 | D6: =IF(COUNTIFS(Resultados!$C$2:$C$2000,"SEC-003",Resultados!$H$2:$H$2000,"NO_CUMPLE")>0,"NO CUMPLE",IF(COUNTIFS(Resultados!$C$2:$C$2000,"SEC-003",Resultados!$H$2:$H$2000,"PARCIAL")+COUNTIFS(Resultados!$C$2:$C$2000,"SEC-003",Resultados!$H$2:$H$2000,"REQUIERE_REVISION_MANUAL")+COUNTIFS(Resultados!$C$2:$C$2000,"SEC-003",Resultados!$H$2:$H$2000,"SIN_EVALUAR")>0,"PARCIAL / PENDIENTE",IF(COUNTIFS(Resultados!$C$2:$C$2000,"SEC-003",Resultados!$H$2:$H$2000,"CUMPLE")>0,"CUMPLE",IF(COUNTIFS(Resultados!$C$2:$C$2000,"SEC-003",Resultados!$H$2:$H$2000,"NO_APLICA")>0,"NO APLICA","SIN DATOS"))))
A7: 3 | B7: El JWT se valida en backend. | C7: SEC-004 | D7: =IF(COUNTIFS(Resultados!$C$2:$C$2000,"SEC-004",Resultados!$H$2:$H$2000,"NO_CUMPLE")>0,"NO CUMPLE",IF(COUNTIFS(Resultados!$C$2:$C$2000,"SEC-004",Resultados!$H$2:$H$2000,"PARCIAL")+COUNTIFS(Resultados!$C$2:$C$2000,"SEC-004",Resultados!$H$2:$H$2000,"REQUIERE_REVISION_MANUAL")+COUNTIFS(Resultados!$C$2:$C$2000,"SEC-004",Resultados!$H$2:$H$2000,"SIN_EVALUAR")>0,"PARCIAL / PENDIENTE",IF(COUNTIFS(Resultados!$C$2:$C$2000,"SEC-004",Resultados!$H$2:$H$2000,"CUMPLE")>0,"CUMPLE",IF(COUNTIFS(Resultados!$C$2:$C$2000,"SEC-004",Resultados!$H$2:$H$2000,"NO_APLICA")>0,"NO APLICA","SIN DATOS"))))
A8: 4 | B8: Los endpoints tienen autorización por rol. | C8: SEC-005, SEC-007 | D8: =IF(COUNTIFS(Resultados!$C$2:$C$2000,"SEC-005",Resultados!$H$2:$H$2000,"NO_CUMPLE")+COUNTIFS(Resultados!$C$2:$C$2000,"SEC-007",Resultados!$H$2:$H$2000,"NO_CUMPLE")>0,"NO CUMPLE",IF(COUNTIFS(Resultados!$C$2:$C$2000,"SEC-005",Resultados!$H$2:$H$2000,"PARCIAL")+COUNTIFS(Resultados!$C$2:$C$2000,"SEC-005",Resultados!$H$2:$H$2000,"REQUIERE_REVISION_MANUAL")+COUNTIFS(Resultados!$C$2:$C$2000,"SEC-005",Resultados!$H$2:$H$2000,"SIN_EVALUAR")+COUNTIFS(Resultados!$C$2:$C$2000,"SEC-007",Resultados!$H$2:$H$2000,"PARCIAL")+COUNTIFS(Resultados!$C$2:$C$2000,"SEC-007",Resultados!$H$2:$H$2000,"REQUIERE_REVISION_MANUAL")+COUNTIFS(Resultados!$C$2:$C$2000,"SEC-007",Resultados!$H$2:$H$2000,"SIN_EVALUAR")>0,"PARCIAL / PENDIENTE",IF(COUNTIFS(Resultados!$C$2:$C$2000,"SEC-005",Resultados!$H$2:$H$2000,"CUMPLE")+COUNTIFS(Resultados!$C$2:$C$2000,"SEC-007",Resultados!$H$2:$H$2000,"CUMPLE")>0,"CUMPLE",IF(COUNTIFS(Resultados!$C$2:$C$2000,"SEC-005",Resultados!$H$2:$H$2000,"NO_APLICA")+COUNTIFS(Resultados!$C$2:$C$2000,"SEC-007",Resultados!$H$2:$H$2000,"NO_APLICA")>0,"NO APLICA","SIN DATOS"))))
A9: 5 | B9: El tenant se obtiene y valida desde un contexto confiable. | C9: SEC-008 | D9: =IF(COUNTIFS(Resultados!$C$2:$C$2000,"SEC-008",Resultados!$H$2:$H$2000,"NO_CUMPLE")>0,"NO CUMPLE",IF(COUNTIFS(Resultados!$C$2:$C$2000,"SEC-008",Resultados!$H$2:$H$2000,"PARCIAL")+COUNTIFS(Resultados!$C$2:$C$2000,"SEC-008",Resultados!$H$2:$H$2000,"REQUIERE_REVISION_MANUAL")+COUNTIFS(Resultados!$C$2:$C$2000,"SEC-008",Resultados!$H$2:$H$2000,"SIN_EVALUAR")>0,"PARCIAL / PENDIENTE",IF(COUNTIFS(Resultados!$C$2:$C$2000,"SEC-008",Resultados!$H$2:$H$2000,"CUMPLE")>0,"CUMPLE",IF(COUNTIFS(Resultados!$C$2:$C$2000,"SEC-008",Resultados!$H$2:$H$2000,"NO_APLICA")>0,"NO APLICA","SIN DATOS"))))
A10: 6 | B10: Las consultas filtran por tenant y año lectivo cuando corresponde. | C10: SEC-009, SEC-021 | D10: =IF(COUNTIFS(Resultados!$C$2:$C$2000,"SEC-009",Resultados!$H$2:$H$2000,"NO_CUMPLE")+COUNTIFS(Resultados!$C$2:$C$2000,"SEC-021",Resultados!$H$2:$H$2000,"NO_CUMPLE")>0,"NO CUMPLE",IF(COUNTIFS(Resultados!$C$2:$C$2000,"SEC-009",Resultados!$H$2:$H$2000,"PARCIAL")+COUNTIFS(Resultados!$C$2:$C$2000,"SEC-009",Resultados!$H$2:$H$2000,"REQUIERE_REVISION_MANUAL")+COUNTIFS(Resultados!$C$2:$C$2000,"SEC-009",Resultados!$H$2:$H$2000,"SIN_EVALUAR")+COUNTIFS(Resultados!$C$2:$C$2000,"SEC-021",Resultados!$H$2:$H$2000,"PARCIAL")+COUNTIFS(Resultados!$C$2:$C$2000,"SEC-021",Resultados!$H$2:$H$2000,"REQUIERE_REVISION_MANUAL")+COUNTIFS(Resultados!$C$2:$C$2000,"SEC-021",Resultados!$H$2:$H$2000,"SIN_EVALUAR")>0,"PARCIAL / PENDIENTE",IF(COUNTIFS(Resultados!$C$2:$C$2000,"SEC-009",Resultados!$H$2:$H$2000,"CUMPLE")+COUNTIFS(Resultados!$C$2:$C$2000,"SEC-021",Resultados!$H$2:$H$2000,"CUMPLE")>0,"CUMPLE",IF(COUNTIFS(Resultados!$C$2:$C$2000,"SEC-009",Resultados!$H$2:$H$2000,"NO_APLICA")+COUNTIFS(Resultados!$C$2:$C$2000,"SEC-021",Resultados!$H$2:$H$2000,"NO_APLICA")>0,"NO APLICA","SIN DATOS"))))
A11: 7 | B11: No existen secretos en el repositorio. | C11: SEC-014 | D11: =IF(COUNTIFS(Resultados!$C$2:$C$2000,"SEC-014",Resultados!$H$2:$H$2000,"NO_CUMPLE")>0,"NO CUMPLE",IF(COUNTIFS(Resultados!$C$2:$C$2000,"SEC-014",Resultados!$H$2:$H$2000,"PARCIAL")+COUNTIFS(Resultados!$C$2:$C$2000,"SEC-014",Resultados!$H$2:$H$2000,"REQUIERE_REVISION_MANUAL")+COUNTIFS(Resultados!$C$2:$C$2000,"SEC-014",Resultados!$H$2:$H$2000,"SIN_EVALUAR")>0,"PARCIAL / PENDIENTE",IF(COUNTIFS(Resultados!$C$2:$C$2000,"SEC-014",Resultados!$H$2:$H$2000,"CUMPLE")>0,"CUMPLE",IF(COUNTIFS(Resultados!$C$2:$C$2000,"SEC-014",Resultados!$H$2:$H$2000,"NO_APLICA")>0,"NO APLICA","SIN DATOS"))))
A12: 8 | B12: Los errores no revelan información sensible. | C12: SEC-017 | D12: =IF(COUNTIFS(Resultados!$C$2:$C$2000,"SEC-017",Resultados!$H$2:$H$2000,"NO_CUMPLE")>0,"NO CUMPLE",IF(COUNTIFS(Resultados!$C$2:$C$2000,"SEC-017",Resultados!$H$2:$H$2000,"PARCIAL")+COUNTIFS(Resultados!$C$2:$C$2000,"SEC-017",Resultados!$H$2:$H$2000,"REQUIERE_REVISION_MANUAL")+COUNTIFS(Resultados!$C$2:$C$2000,"SEC-017",Resultados!$H$2:$H$2000,"SIN_EVALUAR")>0,"PARCIAL / PENDIENTE",IF(COUNTIFS(Resultados!$C$2:$C$2000,"SEC-017",Resultados!$H$2:$H$2000,"CUMPLE")>0,"CUMPLE",IF(COUNTIFS(Resultados!$C$2:$C$2000,"SEC-017",Resultados!$H$2:$H$2000,"NO_APLICA")>0,"NO APLICA","SIN DATOS"))))
A13: 9 | B13: Los logs no contienen tokens ni contraseñas. | C13: SEC-018 | D13: =IF(COUNTIFS(Resultados!$C$2:$C$2000,"SEC-018",Resultados!$H$2:$H$2000,"NO_CUMPLE")>0,"NO CUMPLE",IF(COUNTIFS(Resultados!$C$2:$C$2000,"SEC-018",Resultados!$H$2:$H$2000,"PARCIAL")+COUNTIFS(Resultados!$C$2:$C$2000,"SEC-018",Resultados!$H$2:$H$2000,"REQUIERE_REVISION_MANUAL")+COUNTIFS(Resultados!$C$2:$C$2000,"SEC-018",Resultados!$H$2:$H$2000,"SIN_EVALUAR")>0,"PARCIAL / PENDIENTE",IF(COUNTIFS(Resultados!$C$2:$C$2000,"SEC-018",Resultados!$H$2:$H$2000,"CUMPLE")>0,"CUMPLE",IF(COUNTIFS(Resultados!$C$2:$C$2000,"SEC-018",Resultados!$H$2:$H$2000,"NO_APLICA")>0,"NO APLICA","SIN DATOS"))))
A14: 10 | B14: Existen pruebas de 401, 403, tenant incorrecto e idempotencia. | C14: T01, T03, T04, T07 | D14: =IF(COUNTIFS(Pruebas!$A$2:$A$10,"T01",Pruebas!$E$2:$E$10,"NO_CUMPLE")+COUNTIFS(Pruebas!$A$2:$A$10,"T03",Pruebas!$E$2:$E$10,"NO_CUMPLE")+COUNTIFS(Pruebas!$A$2:$A$10,"T04",Pruebas!$E$2:$E$10,"NO_CUMPLE")+COUNTIFS(Pruebas!$A$2:$A$10,"T07",Pruebas!$E$2:$E$10,"NO_CUMPLE")>0,"NO CUMPLE",IF(COUNTIFS(Pruebas!$A$2:$A$10,"T01",Pruebas!$E$2:$E$10,"PARCIAL")+COUNTIFS(Pruebas!$A$2:$A$10,"T01",Pruebas!$E$2:$E$10,"REQUIERE_REVISION_MANUAL")+COUNTIFS(Pruebas!$A$2:$A$10,"T01",Pruebas!$E$2:$E$10,"SIN_EVALUAR")+COUNTIFS(Pruebas!$A$2:$A$10,"T03",Pruebas!$E$2:$E$10,"PARCIAL")+COUNTIFS(Pruebas!$A$2:$A$10,"T03",Pruebas!$E$2:$E$10,"REQUIERE_REVISION_MANUAL")+COUNTIFS(Pruebas!$A$2:$A$10,"T03",Pruebas!$E$2:$E$10,"SIN_EVALUAR")+COUNTIFS(Pruebas!$A$2:$A$10,"T04",Pruebas!$E$2:$E$10,"PARCIAL")+COUNTIFS(Pruebas!$A$2:$A$10,"T04",Pruebas!$E$2:$E$10,"REQUIERE_REVISION_MANUAL")+COUNTIFS(Pruebas!$A$2:$A$10,"T04",Pruebas!$E$2:$E$10,"SIN_EVALUAR")+COUNTIFS(Pruebas!$A$2:$A$10,"T07",Pruebas!$E$2:$E$10,"PARCIAL")+COUNTIFS(Pruebas!$A$2:$A$10,"T07",Pruebas!$E$2:$E$10,"REQUIERE_REVISION_MANUAL")+COUNTIFS(Pruebas!$A$2:$A$10,"T07",Pruebas!$E$2:$E$10,"SIN_EVALUAR")>0,"PARCIAL / PENDIENTE",IF(COUNTIFS(Pruebas!$A$2:$A$10,"T01",Pruebas!$E$2:$E$10,"CUMPLE")+COUNTIFS(Pruebas!$A$2:$A$10,"T03",Pruebas!$E$2:$E$10,"CUMPLE")+COUNTIFS(Pruebas!$A$2:$A$10,"T04",Pruebas!$E$2:$E$10,"CUMPLE")+COUNTIFS(Pruebas!$A$2:$A$10,"T07",Pruebas!$E$2:$E$10,"CUMPLE")>0,"CUMPLE",IF(COUNTIFS(Pruebas!$A$2:$A$10,"T01",Pruebas!$E$2:$E$10,"NO_APLICA")+COUNTIFS(Pruebas!$A$2:$A$10,"T03",Pruebas!$E$2:$E$10,"NO_APLICA")+COUNTIFS(Pruebas!$A$2:$A$10,"T04",Pruebas!$E$2:$E$10,"NO_APLICA")+COUNTIFS(Pruebas!$A$2:$A$10,"T07",Pruebas!$E$2:$E$10,"NO_APLICA")>0,"NO APLICA","SIN DATOS"))))
A15: 11 | B15: La documentación y los roles coinciden con la configuración real. | C15: SEC-006 | D15: =IF(COUNTIFS(Resultados!$C$2:$C$2000,"SEC-006",Resultados!$H$2:$H$2000,"NO_CUMPLE")>0,"NO CUMPLE",IF(COUNTIFS(Resultados!$C$2:$C$2000,"SEC-006",Resultados!$H$2:$H$2000,"PARCIAL")+COUNTIFS(Resultados!$C$2:$C$2000,"SEC-006",Resultados!$H$2:$H$2000,"REQUIERE_REVISION_MANUAL")+COUNTIFS(Resultados!$C$2:$C$2000,"SEC-006",Resultados!$H$2:$H$2000,"SIN_EVALUAR")>0,"PARCIAL / PENDIENTE",IF(COUNTIFS(Resultados!$C$2:$C$2000,"SEC-006",Resultados!$H$2:$H$2000,"CUMPLE")>0,"CUMPLE",IF(COUNTIFS(Resultados!$C$2:$C$2000,"SEC-006",Resultados!$H$2:$H$2000,"NO_APLICA")>0,"NO APLICA","SIN DATOS"))))
A16: 12 | B16: Las reglas se aplican de forma consistente en todos los proyectos. | C16: — | D16: CUMPLE | E16: La skill trae las mismas 22 reglas que el kit, y el pipeline de cada servicio las evalúa con el mismo kit.

Sheet Reglas
A1: ID | B1: Título | C1: Categoría | D1: Nivel | E1: Severidad base | F1: Aplica a | G1: Método | H1: Requisito del estándar | I1: Qué se verifica | J1: Cumple si | K1: No cumple si
A2: SEC-001 | B2: Proveedor de identidad | C2: Identidad y autenticación | D2: DEBE | E2: Alta | F2: frontend, mobile, gateway, microservicio, infraestructura | G2: Mixto | H2: Todos los clientes y servicios protegidos usan Keycloak como IdP centralizado, con configuración separada por ambiente para que tokens de desarrollo no sean aceptados en producción. | I2: • El issuer/authority/realm configurado apunta a Keycloak (o a un IdP compatible que cumple los mismos controles). • Existe configuración distinta por ambiente (perfiles, archivos environment, variables) y el perfil de producción no apunta al realm o URL de desarrollo. • No hay un segundo mecanismo de autenticación paralelo (usuarios locales, JWT propios firmados con clave simétrica compartida). | J2: El IdP es Keycloak o equivalente compatible y cada ambiente tiene su propio issuer/realm sin cruces. | K2: Producción usa el issuer de desarrollo, hay IdP o autenticación propia paralela, o no hay separación por ambiente.
A3: SEC-002 | B3: Protocolo OIDC sobre OAuth 2.0 | C3: Identidad y autenticación | D3: DEBE | E3: Alta | F3: frontend, mobile, gateway, microservicio | G3: Estático | H3: La autenticación usa OpenID Connect sobre OAuth 2.0; el frontend usa Authorization Code con PKCE; no existen formularios propios para almacenar o validar contraseñas. | I3: • El cliente público usa Authorization Code + PKCE (code_challenge_method S256). • No se usan flujos Implicit ni Resource Owner Password (grant_type=password). • No hay pantallas, endpoints o tablas propias que reciban, almacenen o validen contraseñas de usuarios finales. | J3: El flujo es Code+PKCE (frontend/mobile) y el backend no gestiona contraseñas de usuarios finales. | K3: Se usa Implicit/Password grant, falta PKCE en cliente público, o existe un login propio con contraseñas.
A4: SEC-003 | B4: Clientes de Keycloak por responsabilidad | C4: Identidad y autenticación | D4: DEBE | E4: Alta | F4: frontend, mobile, gateway, microservicio, infraestructura | G4: Estático | H4: Cliente público para frontend sin client_secret embebido; cliente de backend para autenticación de máquina; redirecciones y orígenes limitados a los dominios del ambiente; secretos de clientes confidenciales por variables de entorno o gestor de secretos. | I4: • El frontend/mobile no contiene client_secret en código, bundle, variables públicas ni repositorio. • Existen clientes separados para frontend y para servicios (service accounts). • redirectUris y webOrigins no usan comodín '*' ni dominios de otros ambientes. • El secreto de clientes confidenciales se lee de variables de entorno o gestor de secretos. | J4: Clientes separados, público sin secreto, redirecciones exactas por ambiente y secretos externalizados. | K4: Hay secreto en frontend, redirectUris con '*', o un único cliente compartido para frontend y backend.
A5: SEC-004 | B5: Validación de tokens JWT | C5: Identidad y autenticación | D5: DEBE | E5: Crítica | F5: gateway, microservicio | G5: Mixto | H5: Gateway y cada microservicio protegido validan el JWT: firma con claves públicas de Keycloak, iss, aud cuando aplique, exp y formato. No se confía en un identificador de usuario enviado por header, query o body si no coincide con la identidad autenticada. | I5: • Existe un resource server / middleware que valida la firma contra el JWKS de Keycloak. • Se valida issuer y expiración; se valida audience cuando el servicio lo requiere. • No hay decodificación sin verificación (decode sin verify, alg none, ignoreExpiration). • El userId usado en la lógica sale del token, no de header/param/body sin contrastar. • No hay rutas protegidas marcadas como permitAll por error. | J5: Firma, iss y exp se validan en el backend; audience se valida donde corresponde; la identidad proviene del token. | K5: No se valida la firma, el issuer o la expiración, o se confía en la identidad enviada por el cliente.
A6: SEC-005 | B6: Autorización en backend | C6: Autorización y roles | D6: DEBE | E6: Crítica | F6: gateway, microservicio | G6: Estático | H6: Los permisos se validan en el gateway y, de forma independiente, en el microservicio que ejecuta la operación. Ocultar un botón en el frontend no es autorización. | I6: • El gateway aplica reglas de autorización por ruta/rol. • Cada microservicio autoriza por sí mismo (anotaciones, reglas de seguridad o middleware) sin depender del gateway. • Ningún endpoint de negocio queda sin regla de autorización explícita. | J6: Todos los endpoints de negocio tienen autorización explícita validada en el propio servicio. | K6: Hay endpoints de negocio sin autorización, o el servicio confía únicamente en el gateway o en el frontend.
A7: SEC-006 | B7: Roles de negocio consistentes | C7: Autorización y roles | D7: DEBERÍA | E7: Media | F7: frontend, gateway, microservicio, infraestructura | G7: Estático | H7: El sistema usa roles de negocio claros (ADMIN, DIRECTOR, COORDINATOR, TEACHER, SECRETARY u otros definidos). Los nombres definitivos DEBEN ser consistentes entre Keycloak, gateway, microservicios y documentación. | I7: • El conjunto de roles usado en código coincide con los roles definidos en Keycloak (realm export). • Los nombres de rol son idénticos (mayúsculas, prefijos ROLE_) entre componentes. • La documentación del proyecto lista los mismos roles que la configuración real. | J7: Los roles coinciden entre Keycloak, código y documentación. | K7: Hay roles usados en código que no existen en Keycloak, nombres distintos entre componentes o documentación desactualizada.
A8: SEC-007 | B8: Menor privilegio por endpoint | C8: Autorización y roles | D8: DEBE | E8: Alta | F8: gateway, microservicio | G8: Estático | H8: Cada endpoint otorga solo el permiso necesario; no se usa un rol administrativo como solución general; lectura, creación, actualización y eliminación DEBERÍAN tener permisos diferenciados cuando el riesgo lo justifique. | I8: • No hay hasRole('ADMIN') (o equivalente) aplicado de forma generalizada para evitar errores de permisos. • Los endpoints de escritura/borrado exigen un permiso más restrictivo que los de lectura cuando el riesgo lo justifica. • Los roles asignados a cada endpoint se corresponden con quién necesita realmente la operación. | J8: Los permisos están acotados por endpoint y operación. | K8: Se usa ADMIN o 'authenticated' de forma indiscriminada, o endpoints sensibles quedan abiertos a roles que no los necesitan.
A9: SEC-008 | B9: Tenant derivado de la identidad autenticada | C9: Aislamiento multi-tenant | D9: DEBE | E9: Crítica | F9: frontend, mobile, gateway, microservicio | G9: Mixto | H9: Cada solicitud institucional se resuelve con el tenant asociado a la identidad autenticada o a un contexto confiable validado por el gateway. El frontend no puede cambiar de institución enviando solo otro tenantId. | I9: • El tenant efectivo se obtiene de un claim del token o de un header que el gateway sobrescribe y valida. • El gateway elimina o sobrescribe cualquier header de tenant enviado por el cliente. • Los servicios no aceptan tenantId de path/query/body como fuente de verdad sin contrastarlo con el tenant autenticado. • El frontend no puede elegir libremente el tenant (selección validada contra los tenants permitidos del usuario). | J9: El tenant sale de la identidad o de un contexto validado por el gateway y no es manipulable desde el cliente. | K9: Cambiar el tenantId en la petición cambia la institución consultada.
A10: SEC-009 | B10: Filtro obligatorio por tenant en datos | C10: Aislamiento multi-tenant | D10: DEBE | E10: Crítica | F10: microservicio | G10: Estático | H10: Las consultas y mutaciones de datos institucionales filtran por tenant. Claves únicas, índices y reglas de negocio DEBERÍAN considerar el tenant cuando los datos puedan repetirse entre instituciones. | I10: • Todas las consultas (JPA, SQL nativo, Mongo, R2DBC) sobre datos institucionales incluyen el predicado de tenant, o hay un filtro global confiable. • Las mutaciones (update/delete) también están acotadas por tenant. • Claves únicas e índices incluyen el tenant donde los valores pueden repetirse entre instituciones. | J10: No se encuentran accesos a datos institucionales sin acotar por tenant. | K10: Existen consultas o mutaciones de datos institucionales sin filtro de tenant.
A11: SEC-010 | B11: Prevención de fuga de datos entre tenants | C11: Aislamiento multi-tenant | D11: DEBE | E11: Crítica | F11: gateway, microservicio | G11: Mixto | H11: El sistema rechaza el acceso cuando usuario, recurso, estudiante, clase o institución no pertenecen al mismo contexto autorizado. Los errores no revelan información de otro tenant. | I11: • Antes de devolver o modificar un recurso se verifica que pertenece al tenant autorizado. • Los errores por recurso de otro tenant no distinguen 'existe pero no es tuyo' de 'no existe' ni incluyen datos ajenos. • Existen pruebas automáticas de acceso cruzado entre tenants. | J11: El acceso cruzado es rechazado y los errores no filtran información. | K11: Un usuario puede leer o modificar recursos de otro tenant, o los mensajes revelan datos de otro tenant.
A12: SEC-011 | B12: Comunicación autenticada entre servicios | C12: Seguridad entre microservicios | D12: DEBE | E12: Alta | F12: gateway, microservicio, integracion | G12: Estático | H12: Las llamadas entre servicios usan un contexto de autenticación válido. Con propagación de token, el receptor lo vuelve a validar; con credencial de servicio, esta se limita al servicio y permisos necesarios. | I12: • Los clientes HTTP internos (WebClient, RestTemplate, Feign, axios, fetch) envían un token o credencial de servicio. • El servicio receptor valida de nuevo el JWT; no confía en headers internos sin validar (X-Internal-*, X-User-*). • Las credenciales de servicio (client_credentials) tienen roles/scopes mínimos. | J12: Toda llamada interna lleva identidad válida y es verificada por el receptor. | K12: Hay llamadas internas sin autenticación, headers internos confiables sin validar o credenciales de servicio con privilegios excesivos.
... A23: SEC-022 | B23: Idempotencia y control de concurrencia | C23: Integridad transversal | D23: DEBERÍA | E23: Media | F23: microservicio, integracion | G23: Mixto | H23: Las operaciones de creación o procesamiento masivo DEBERÍAN ser idempotentes. Reintentar por pérdida de conexión no debe crear duplicados ni cambiar un registro confirmado sin autorización. | I23: • Las operaciones masivas y de creación usan claves de idempotencia, upsert o restricciones únicas por clave natural. • Existe control de concurrencia (versionado optimista, bloqueo) en entidades editables. • Los registros confirmados no se modifican en reintentos sin autorización explícita. • Consumidores de colas toleran mensajes duplicados. | J23: Los reintentos no generan duplicados ni sobrescrituras indebidas. | K23: Un reintento puede duplicar datos o alterar registros confirmados.

Sheet Leyenda
A1: Leyenda, método de cálculo y supuestos
A3: Estados y peso en el cumplimiento
A4: Estado | B4: Significado | C4: Peso
A5: CUMPLE | B5: Todas las verificaciones obligatorias de la regla tienen evidencia positiva. | C5: 1
A6: PARCIAL | B6: Algunas verificaciones se cumplen y otras no, o se cumple solo en parte del componente. | C6: 0.5
A7: NO_CUMPLE | B7: Hay evidencia de incumplimiento, o el control esperado no existe tras revisar el código relevante. | C7: 0
A8: NO_APLICA | B8: La regla no aplica al componente; debe justificarse en la observación. | C8: 1
A9: REQUIERE_REVISION_MANUAL | B9: No se puede decidir con el código disponible (configuración externa, prueba dinámica, decisión de negocio). | C9: n/a
A10: SIN_EVALUAR | B10: Estado automático del generador cuando una regla aplicable no tiene resultado. | C10: n/a
A11: Los pesos en azul/amarillo son supuestos editables: PARCIAL=0.5 es una convención de este reporte, no del estándar.
A13: Niveles normativos del estándar
A14: DEBE | B14: Requisito obligatorio. Un NO_CUMPLE bloquea el veredicto.
A15: DEBERÍA | B15: Recomendación; solo puede omitirse con justificación.
A17: Notas de lectura
A18: • Celdas amarillas con texto azul = datos para completar (responsable, fechas, comentarios, pesos).
A19: • Resumen, Matriz y Checklist son fórmulas sobre la hoja Resultados; al corregir un estado se recalculan.
A20: • La hoja Hallazgos es una instantánea de los NO_CUMPLE/PARCIAL al momento de generar el reporte.
A21: • El nivel de cada regla (DEBE/DEBERÍA) es el predominante en el texto del estándar; algunas reglas mezclan ambos (p. ej. SEC-007, SEC-009) y el detalle está en la hoja Reglas.
A22: • El generador enmascara automáticamente secretos evidentes (JWT, claves privadas, password=...) en la evidencia.
A23: • Catálogo de reglas: versión 1.0.0 del estándar (Propuesta para revisión).
